{
 "cells": [
  {
   "cell_type": "markdown",
   "id": "f0c3adfe",
   "metadata": {},
   "source": [
    "### 使用 cifar-10 数据集完成分类任务，可以 10 分类也可以 2 分类，自己把握"
   ]
  },
  {
   "cell_type": "code",
   "execution_count": 45,
   "id": "56d655ee",
   "metadata": {},
   "outputs": [
    {
     "name": "stdout",
     "output_type": "stream",
     "text": [
      "ERROR! Session/line number was not unique in database. History logging moved to new session 329\n"
     ]
    }
   ],
   "source": [
    "import tensorflow as tf\n",
    "import numpy as np\n",
    "import matplotlib.pyplot as plt\n",
    "import _pickle as pickle\n",
    "import seaborn\n",
    "import numpy as np\n",
    "import os\n",
    "import pickle"
   ]
  },
  {
   "cell_type": "code",
   "execution_count": 46,
   "id": "ec311307",
   "metadata": {},
   "outputs": [],
   "source": [
    "def unpickle(filename):\n",
    "    '''解压数据'''\n",
    "    # Python2\n",
    "    # with open(filename) as f:\n",
    "    #     d = pickle.load(f)\n",
    "    #     return d\n",
    "    \n",
    "    # Python3\n",
    "    with open(filename, 'rb') as f:\n",
    "        d = pickle.load(f, encoding='latin1')\n",
    "        return d\n",
    "\n",
    "\n",
    "def onehot(labels):\n",
    "    '''one-hot 编码'''\n",
    "    n_sample = len(labels)\n",
    "    n_class = max(labels) + 1\n",
    "    onehot_labels = np.zeros((n_sample, n_class))\n",
    "    onehot_labels[np.arange(n_sample), labels] = 1\n",
    "    return onehot_labels"
   ]
  },
  {
   "cell_type": "code",
   "execution_count": 47,
   "id": "d5e810ff",
   "metadata": {},
   "outputs": [],
   "source": [
    "data1 = unpickle('data/data_batch_1')\n",
    "data2 = unpickle('data/data_batch_2')\n",
    "data3 = unpickle('data/data_batch_3')\n",
    "data4 = unpickle('data/data_batch_4')\n",
    "data5 = unpickle('data/data_batch_5')\n",
    "X_train = np.concatenate((data1['data'], data2['data'], data3['data'], data4['data'], data5['data']), axis=0)\n",
    "y_train = np.concatenate((data1['labels'], data2['labels'], data3['labels'], data4['labels'], data5['labels']), axis=0)\n",
    "y_train = onehot(y_train)\n",
    "# 测试数据集\n",
    "test = unpickle('data/test_batch')\n",
    "X_test = test['data'][:5000, :]\n",
    "y_test = onehot(test['labels'])[:5000, :]"
   ]
  },
  {
   "cell_type": "code",
   "execution_count": 48,
   "id": "8b51dab9",
   "metadata": {
    "scrolled": true
   },
   "outputs": [
    {
     "name": "stdout",
     "output_type": "stream",
     "text": [
      "Training dataset shape: (50000, 3072)\n",
      "Training labels shape: (50000, 10)\n",
      "Testing dataset shape: (5000, 3072)\n",
      "Testing labels shape: (5000, 10)\n"
     ]
    }
   ],
   "source": [
    "print('Training dataset shape:', X_train.shape)\n",
    "print('Training labels shape:', y_train.shape)\n",
    "print('Testing dataset shape:', X_test.shape)\n",
    "print('Testing labels shape:', y_test.shape)"
   ]
  },
  {
   "cell_type": "code",
   "execution_count": null,
   "id": "33c916c6",
   "metadata": {
    "scrolled": false
   },
   "outputs": [
    {
     "name": "stderr",
     "output_type": "stream",
     "text": [
      "ERROR:root:Internal Python error in the inspect module.\n",
      "Below is the traceback from this internal error.\n",
      "\n",
      "ERROR:root:Internal Python error in the inspect module.\n",
      "Below is the traceback from this internal error.\n",
      "\n",
      "ERROR:root:Internal Python error in the inspect module.\n",
      "Below is the traceback from this internal error.\n",
      "\n"
     ]
    },
    {
     "name": "stdout",
     "output_type": "stream",
     "text": [
      "Traceback (most recent call last):\n",
      "  File \"C:\\Users\\29459\\anaconda3\\envs\\python37\\lib\\site-packages\\IPython\\core\\interactiveshell.py\", line 3437, in run_code\n",
      "    exec(code_obj, self.user_global_ns, self.user_ns)\n",
      "  File \"<ipython-input-49-df2b0f3258bd>\", line 2, in <module>\n",
      "    sns.countplot(y_train.ravel(), ax=ax[0], palette = ['#7DB0BB'])\n",
      "NameError: name 'sns' is not defined\n",
      "\n",
      "During handling of the above exception, another exception occurred:\n",
      "\n",
      "Traceback (most recent call last):\n",
      "  File \"C:\\Users\\29459\\anaconda3\\envs\\python37\\lib\\site-packages\\IPython\\core\\interactiveshell.py\", line 2061, in showtraceback\n",
      "    stb = value._render_traceback_()\n",
      "AttributeError: 'NameError' object has no attribute '_render_traceback_'\n",
      "\n",
      "During handling of the above exception, another exception occurred:\n",
      "\n",
      "Traceback (most recent call last):\n",
      "  File \"C:\\Users\\29459\\anaconda3\\envs\\python37\\lib\\site-packages\\IPython\\core\\ultratb.py\", line 1101, in get_records\n",
      "    return _fixed_getinnerframes(etb, number_of_lines_of_context, tb_offset)\n",
      "  File \"C:\\Users\\29459\\anaconda3\\envs\\python37\\lib\\site-packages\\IPython\\core\\ultratb.py\", line 248, in wrapped\n",
      "    return f(*args, **kwargs)\n",
      "  File \"C:\\Users\\29459\\anaconda3\\envs\\python37\\lib\\site-packages\\IPython\\core\\ultratb.py\", line 281, in _fixed_getinnerframes\n",
      "    records = fix_frame_records_filenames(inspect.getinnerframes(etb, context))\n",
      "  File \"C:\\Users\\29459\\anaconda3\\envs\\python37\\lib\\inspect.py\", line 1502, in getinnerframes\n",
      "    frameinfo = (tb.tb_frame,) + getframeinfo(tb, context)\n",
      "  File \"C:\\Users\\29459\\anaconda3\\envs\\python37\\lib\\inspect.py\", line 1460, in getframeinfo\n",
      "    filename = getsourcefile(frame) or getfile(frame)\n",
      "  File \"C:\\Users\\29459\\anaconda3\\envs\\python37\\lib\\inspect.py\", line 696, in getsourcefile\n",
      "    if getattr(getmodule(object, filename), '__loader__', None) is not None:\n",
      "  File \"C:\\Users\\29459\\anaconda3\\envs\\python37\\lib\\inspect.py\", line 733, in getmodule\n",
      "    if ismodule(module) and hasattr(module, '__file__'):\n",
      "  File \"C:\\Users\\29459\\anaconda3\\envs\\python37\\lib\\site-packages\\tensorflow\\__init__.py\", line 50, in __getattr__\n",
      "    module = self._load()\n",
      "  File \"C:\\Users\\29459\\anaconda3\\envs\\python37\\lib\\site-packages\\tensorflow\\__init__.py\", line 44, in _load\n",
      "    module = _importlib.import_module(self.__name__)\n",
      "  File \"C:\\Users\\29459\\anaconda3\\envs\\python37\\lib\\importlib\\__init__.py\", line 127, in import_module\n",
      "    return _bootstrap._gcd_import(name[level:], package, level)\n",
      "  File \"<frozen importlib._bootstrap>\", line 1006, in _gcd_import\n",
      "  File \"<frozen importlib._bootstrap>\", line 983, in _find_and_load\n",
      "  File \"<frozen importlib._bootstrap>\", line 965, in _find_and_load_unlocked\n",
      "ModuleNotFoundError: No module named 'tensorflow_core.estimator'\n",
      "Traceback (most recent call last):\n",
      "  File \"C:\\Users\\29459\\anaconda3\\envs\\python37\\lib\\site-packages\\IPython\\core\\interactiveshell.py\", line 3437, in run_code\n",
      "    exec(code_obj, self.user_global_ns, self.user_ns)\n",
      "  File \"<ipython-input-49-df2b0f3258bd>\", line 2, in <module>\n",
      "    sns.countplot(y_train.ravel(), ax=ax[0], palette = ['#7DB0BB'])\n",
      "NameError: name 'sns' is not defined\n",
      "\n",
      "During handling of the above exception, another exception occurred:\n",
      "\n",
      "Traceback (most recent call last):\n",
      "  File \"C:\\Users\\29459\\anaconda3\\envs\\python37\\lib\\site-packages\\IPython\\core\\interactiveshell.py\", line 2061, in showtraceback\n",
      "    stb = value._render_traceback_()\n",
      "AttributeError: 'NameError' object has no attribute '_render_traceback_'\n",
      "\n",
      "During handling of the above exception, another exception occurred:\n",
      "\n",
      "Traceback (most recent call last):\n",
      "  File \"C:\\Users\\29459\\anaconda3\\envs\\python37\\lib\\site-packages\\IPython\\core\\interactiveshell.py\", line 3357, in run_ast_nodes\n",
      "    if (await self.run_code(code, result,  async_=asy)):\n",
      "  File \"C:\\Users\\29459\\anaconda3\\envs\\python37\\lib\\site-packages\\IPython\\core\\interactiveshell.py\", line 3454, in run_code\n",
      "    self.showtraceback(running_compiled_code=True)\n",
      "  File \"C:\\Users\\29459\\anaconda3\\envs\\python37\\lib\\site-packages\\IPython\\core\\interactiveshell.py\", line 2064, in showtraceback\n",
      "    value, tb, tb_offset=tb_offset)\n",
      "  File \"C:\\Users\\29459\\anaconda3\\envs\\python37\\lib\\site-packages\\IPython\\core\\ultratb.py\", line 1368, in structured_traceback\n",
      "    self, etype, value, tb, tb_offset, number_of_lines_of_context)\n",
      "  File \"C:\\Users\\29459\\anaconda3\\envs\\python37\\lib\\site-packages\\IPython\\core\\ultratb.py\", line 1268, in structured_traceback\n",
      "    self, etype, value, tb, tb_offset, number_of_lines_of_context\n",
      "  File \"C:\\Users\\29459\\anaconda3\\envs\\python37\\lib\\site-packages\\IPython\\core\\ultratb.py\", line 1125, in structured_traceback\n",
      "    tb_offset)\n",
      "  File \"C:\\Users\\29459\\anaconda3\\envs\\python37\\lib\\site-packages\\IPython\\core\\ultratb.py\", line 1082, in format_exception_as_a_whole\n",
      "    last_unique, recursion_repeat = find_recursion(orig_etype, evalue, records)\n",
      "  File \"C:\\Users\\29459\\anaconda3\\envs\\python37\\lib\\site-packages\\IPython\\core\\ultratb.py\", line 382, in find_recursion\n",
      "    return len(records), 0\n",
      "TypeError: object of type 'NoneType' has no len()\n",
      "\n",
      "During handling of the above exception, another exception occurred:\n",
      "\n",
      "Traceback (most recent call last):\n",
      "  File \"C:\\Users\\29459\\anaconda3\\envs\\python37\\lib\\site-packages\\IPython\\core\\interactiveshell.py\", line 2061, in showtraceback\n",
      "    stb = value._render_traceback_()\n",
      "AttributeError: 'TypeError' object has no attribute '_render_traceback_'\n",
      "\n",
      "During handling of the above exception, another exception occurred:\n",
      "\n",
      "Traceback (most recent call last):\n",
      "  File \"C:\\Users\\29459\\anaconda3\\envs\\python37\\lib\\site-packages\\IPython\\core\\ultratb.py\", line 1101, in get_records\n",
      "    return _fixed_getinnerframes(etb, number_of_lines_of_context, tb_offset)\n",
      "  File \"C:\\Users\\29459\\anaconda3\\envs\\python37\\lib\\site-packages\\IPython\\core\\ultratb.py\", line 248, in wrapped\n",
      "    return f(*args, **kwargs)\n",
      "  File \"C:\\Users\\29459\\anaconda3\\envs\\python37\\lib\\site-packages\\IPython\\core\\ultratb.py\", line 281, in _fixed_getinnerframes\n",
      "    records = fix_frame_records_filenames(inspect.getinnerframes(etb, context))\n",
      "  File \"C:\\Users\\29459\\anaconda3\\envs\\python37\\lib\\inspect.py\", line 1502, in getinnerframes\n",
      "    frameinfo = (tb.tb_frame,) + getframeinfo(tb, context)\n",
      "  File \"C:\\Users\\29459\\anaconda3\\envs\\python37\\lib\\inspect.py\", line 1460, in getframeinfo\n",
      "    filename = getsourcefile(frame) or getfile(frame)\n",
      "  File \"C:\\Users\\29459\\anaconda3\\envs\\python37\\lib\\inspect.py\", line 696, in getsourcefile\n",
      "    if getattr(getmodule(object, filename), '__loader__', None) is not None:\n",
      "  File \"C:\\Users\\29459\\anaconda3\\envs\\python37\\lib\\inspect.py\", line 733, in getmodule\n",
      "    if ismodule(module) and hasattr(module, '__file__'):\n",
      "  File \"C:\\Users\\29459\\anaconda3\\envs\\python37\\lib\\site-packages\\tensorflow\\__init__.py\", line 50, in __getattr__\n",
      "    module = self._load()\n",
      "  File \"C:\\Users\\29459\\anaconda3\\envs\\python37\\lib\\site-packages\\tensorflow\\__init__.py\", line 44, in _load\n",
      "    module = _importlib.import_module(self.__name__)\n",
      "  File \"C:\\Users\\29459\\anaconda3\\envs\\python37\\lib\\importlib\\__init__.py\", line 127, in import_module\n",
      "    return _bootstrap._gcd_import(name[level:], package, level)\n",
      "  File \"<frozen importlib._bootstrap>\", line 1006, in _gcd_import\n",
      "  File \"<frozen importlib._bootstrap>\", line 983, in _find_and_load\n",
      "  File \"<frozen importlib._bootstrap>\", line 965, in _find_and_load_unlocked\n",
      "ModuleNotFoundError: No module named 'tensorflow_core.estimator'\n",
      "Traceback (most recent call last):\n",
      "  File \"C:\\Users\\29459\\anaconda3\\envs\\python37\\lib\\site-packages\\IPython\\core\\interactiveshell.py\", line 3437, in run_code\n",
      "    exec(code_obj, self.user_global_ns, self.user_ns)\n",
      "  File \"<ipython-input-49-df2b0f3258bd>\", line 2, in <module>\n",
      "    sns.countplot(y_train.ravel(), ax=ax[0], palette = ['#7DB0BB'])\n",
      "NameError: name 'sns' is not defined\n",
      "\n",
      "During handling of the above exception, another exception occurred:\n",
      "\n",
      "Traceback (most recent call last):\n",
      "  File \"C:\\Users\\29459\\anaconda3\\envs\\python37\\lib\\site-packages\\IPython\\core\\interactiveshell.py\", line 2061, in showtraceback\n",
      "    stb = value._render_traceback_()\n",
      "AttributeError: 'NameError' object has no attribute '_render_traceback_'\n",
      "\n",
      "During handling of the above exception, another exception occurred:\n",
      "\n",
      "Traceback (most recent call last):\n",
      "  File \"C:\\Users\\29459\\anaconda3\\envs\\python37\\lib\\site-packages\\IPython\\core\\interactiveshell.py\", line 3357, in run_ast_nodes\n",
      "    if (await self.run_code(code, result,  async_=asy)):\n",
      "  File \"C:\\Users\\29459\\anaconda3\\envs\\python37\\lib\\site-packages\\IPython\\core\\interactiveshell.py\", line 3454, in run_code\n",
      "    self.showtraceback(running_compiled_code=True)\n",
      "  File \"C:\\Users\\29459\\anaconda3\\envs\\python37\\lib\\site-packages\\IPython\\core\\interactiveshell.py\", line 2064, in showtraceback\n",
      "    value, tb, tb_offset=tb_offset)\n",
      "  File \"C:\\Users\\29459\\anaconda3\\envs\\python37\\lib\\site-packages\\IPython\\core\\ultratb.py\", line 1368, in structured_traceback\n",
      "    self, etype, value, tb, tb_offset, number_of_lines_of_context)\n",
      "  File \"C:\\Users\\29459\\anaconda3\\envs\\python37\\lib\\site-packages\\IPython\\core\\ultratb.py\", line 1268, in structured_traceback\n",
      "    self, etype, value, tb, tb_offset, number_of_lines_of_context\n",
      "  File \"C:\\Users\\29459\\anaconda3\\envs\\python37\\lib\\site-packages\\IPython\\core\\ultratb.py\", line 1125, in structured_traceback\n",
      "    tb_offset)\n",
      "  File \"C:\\Users\\29459\\anaconda3\\envs\\python37\\lib\\site-packages\\IPython\\core\\ultratb.py\", line 1082, in format_exception_as_a_whole\n",
      "    last_unique, recursion_repeat = find_recursion(orig_etype, evalue, records)\n",
      "  File \"C:\\Users\\29459\\anaconda3\\envs\\python37\\lib\\site-packages\\IPython\\core\\ultratb.py\", line 382, in find_recursion\n",
      "    return len(records), 0\n",
      "TypeError: object of type 'NoneType' has no len()\n",
      "\n",
      "During handling of the above exception, another exception occurred:\n",
      "\n",
      "Traceback (most recent call last):\n",
      "  File \"C:\\Users\\29459\\anaconda3\\envs\\python37\\lib\\site-packages\\IPython\\core\\interactiveshell.py\", line 2061, in showtraceback\n",
      "    stb = value._render_traceback_()\n",
      "AttributeError: 'TypeError' object has no attribute '_render_traceback_'\n",
      "\n",
      "During handling of the above exception, another exception occurred:\n",
      "\n",
      "Traceback (most recent call last):\n",
      "  File \"C:\\Users\\29459\\anaconda3\\envs\\python37\\lib\\site-packages\\IPython\\core\\interactiveshell.py\", line 2940, in _run_cell\n",
      "    return runner(coro)\n",
      "  File \"C:\\Users\\29459\\anaconda3\\envs\\python37\\lib\\site-packages\\IPython\\core\\async_helpers.py\", line 68, in _pseudo_sync_runner\n",
      "    coro.send(None)\n",
      "  File \"C:\\Users\\29459\\anaconda3\\envs\\python37\\lib\\site-packages\\IPython\\core\\interactiveshell.py\", line 3166, in run_cell_async\n",
      "    interactivity=interactivity, compiler=compiler, result=result)\n",
      "  File \"C:\\Users\\29459\\anaconda3\\envs\\python37\\lib\\site-packages\\IPython\\core\\interactiveshell.py\", line 3376, in run_ast_nodes\n",
      "    self.showtraceback()\n",
      "  File \"C:\\Users\\29459\\anaconda3\\envs\\python37\\lib\\site-packages\\IPython\\core\\interactiveshell.py\", line 2064, in showtraceback\n",
      "    value, tb, tb_offset=tb_offset)\n",
      "  File \"C:\\Users\\29459\\anaconda3\\envs\\python37\\lib\\site-packages\\IPython\\core\\ultratb.py\", line 1368, in structured_traceback\n",
      "    self, etype, value, tb, tb_offset, number_of_lines_of_context)\n",
      "  File \"C:\\Users\\29459\\anaconda3\\envs\\python37\\lib\\site-packages\\IPython\\core\\ultratb.py\", line 1268, in structured_traceback\n",
      "    self, etype, value, tb, tb_offset, number_of_lines_of_context\n",
      "  File \"C:\\Users\\29459\\anaconda3\\envs\\python37\\lib\\site-packages\\IPython\\core\\ultratb.py\", line 1143, in structured_traceback\n",
      "    chained_exceptions_tb_offset)\n",
      "  File \"C:\\Users\\29459\\anaconda3\\envs\\python37\\lib\\site-packages\\IPython\\core\\ultratb.py\", line 1082, in format_exception_as_a_whole\n",
      "    last_unique, recursion_repeat = find_recursion(orig_etype, evalue, records)\n",
      "  File \"C:\\Users\\29459\\anaconda3\\envs\\python37\\lib\\site-packages\\IPython\\core\\ultratb.py\", line 382, in find_recursion\n",
      "    return len(records), 0\n",
      "TypeError: object of type 'NoneType' has no len()\n",
      "\n",
      "During handling of the above exception, another exception occurred:\n",
      "\n",
      "Traceback (most recent call last):\n",
      "  File \"C:\\Users\\29459\\anaconda3\\envs\\python37\\lib\\site-packages\\IPython\\core\\interactiveshell.py\", line 2061, in showtraceback\n",
      "    stb = value._render_traceback_()\n",
      "AttributeError: 'TypeError' object has no attribute '_render_traceback_'\n",
      "\n",
      "During handling of the above exception, another exception occurred:\n",
      "\n",
      "Traceback (most recent call last):\n",
      "  File \"C:\\Users\\29459\\anaconda3\\envs\\python37\\lib\\site-packages\\IPython\\core\\ultratb.py\", line 1101, in get_records\n",
      "    return _fixed_getinnerframes(etb, number_of_lines_of_context, tb_offset)\n",
      "  File \"C:\\Users\\29459\\anaconda3\\envs\\python37\\lib\\site-packages\\IPython\\core\\ultratb.py\", line 248, in wrapped\n",
      "    return f(*args, **kwargs)\n",
      "  File \"C:\\Users\\29459\\anaconda3\\envs\\python37\\lib\\site-packages\\IPython\\core\\ultratb.py\", line 281, in _fixed_getinnerframes\n",
      "    records = fix_frame_records_filenames(inspect.getinnerframes(etb, context))\n",
      "  File \"C:\\Users\\29459\\anaconda3\\envs\\python37\\lib\\inspect.py\", line 1502, in getinnerframes\n",
      "    frameinfo = (tb.tb_frame,) + getframeinfo(tb, context)\n",
      "  File \"C:\\Users\\29459\\anaconda3\\envs\\python37\\lib\\inspect.py\", line 1460, in getframeinfo\n",
      "    filename = getsourcefile(frame) or getfile(frame)\n",
      "  File \"C:\\Users\\29459\\anaconda3\\envs\\python37\\lib\\inspect.py\", line 696, in getsourcefile\n",
      "    if getattr(getmodule(object, filename), '__loader__', None) is not None:\n",
      "  File \"C:\\Users\\29459\\anaconda3\\envs\\python37\\lib\\inspect.py\", line 733, in getmodule\n",
      "    if ismodule(module) and hasattr(module, '__file__'):\n",
      "  File \"C:\\Users\\29459\\anaconda3\\envs\\python37\\lib\\site-packages\\tensorflow\\__init__.py\", line 50, in __getattr__\n",
      "    module = self._load()\n",
      "  File \"C:\\Users\\29459\\anaconda3\\envs\\python37\\lib\\site-packages\\tensorflow\\__init__.py\", line 44, in _load\n",
      "    module = _importlib.import_module(self.__name__)\n",
      "  File \"C:\\Users\\29459\\anaconda3\\envs\\python37\\lib\\importlib\\__init__.py\", line 127, in import_module\n",
      "    return _bootstrap._gcd_import(name[level:], package, level)\n",
      "  File \"<frozen importlib._bootstrap>\", line 1006, in _gcd_import\n",
      "  File \"<frozen importlib._bootstrap>\", line 983, in _find_and_load\n",
      "  File \"<frozen importlib._bootstrap>\", line 965, in _find_and_load_unlocked\n",
      "ModuleNotFoundError: No module named 'tensorflow_core.estimator'\n"
     ]
    },
    {
     "data": {
      "image/png": "iVBORw0KGgoAAAANSUhEUgAAA3IAAAEzCAYAAAB0TDEBAAAAOXRFWHRTb2Z0d2FyZQBNYXRwbG90bGliIHZlcnNpb24zLjMuNCwgaHR0cHM6Ly9tYXRwbG90bGliLm9yZy8QVMy6AAAACXBIWXMAAAsTAAALEwEAmpwYAAATFklEQVR4nO3dX4jl913/8dfbXQNa/6SYVeomwSixcS8aacdYRH9Gy0+zuVmEXiQVg0FYgo14meCFXvRGLwQpTV2WEkJvzMXPoKvEhh+IVqjRTKBNuy0pY4rJmEI2Viq0YNj27cWMZhxnM9/v7jl7zifzeMDAfM/5ZObDh+x585xzZk51dwAAABjHd6x6AwAAAMwj5AAAAAYj5AAAAAYj5AAAAAYj5AAAAAYj5AAAAAZzaMhV1eNV9VpVfeEK91dVfbSqtqrqhap67+K3CQDrx4wEYFWmPCP3RJJ73uL+00lu3/04m+SPr31bADCEJ2JGArACh4Zcd386ydfeYsmZJJ/sHc8mubGq3rWoDQLAujIjAViVRfyO3Mkkr+y53t69DQCOOjMSgKU4voCvUQfc1gcurDqbnZeW5B3veMf77rjjjgV8ewDW3fPPP/96d59Y9T5WwIwE4IquZT4uIuS2k9yy5/rmJK8etLC7zyc5nyQbGxu9ubm5gG8PwLqrqn9e9R5WxIwE4IquZT4u4qWVF5I8sPuXud6f5Ovd/dUFfF0AGJ0ZCcBSHPqMXFX9SZK7k9xUVdtJfi/JdyZJd59L8nSSe5NsJflmkgeXtVkAWCdmJACrcmjIdff9h9zfST68sB0BwCDMSABWZREvrQQAAOA6EnIAAACDEXIAAACDEXIAAACDEXIAAACDEXIAAACDEXIAAACDEXIAAACDEXIAAACDEXIAAACDEXIAAACDEXIAAACDEXIAAACDEXIAAACDEXIAAACDEXIAAACDEXIAAACDEXIAAACDEXIAAACDEXIAAACDEXIAAACDEXIAAACDEXIAAACDEXIAAACDEXIAAACDEXIAAACDEXIAAACDEXIAAACDEXIAAACDEXIAAACDEXIAAACDEXIAAACDEXIAAACDEXIAAACDEXIAAACDEXIAAACDEXIAAACDEXIAAACDEXIAAACDEXIAAACDEXIAAACDEXIAAACDEXIAAACDEXIAAACDEXIAAACDEXIAAACDmRRyVXVPVb1YVVtV9egB939/Vf1FVX2uqi5W1YOL3yoArBfzEYBVOTTkqupYkseSnE5yKsn9VXVq37IPJ/lid9+Z5O4kf1hVNyx4rwCwNsxHAFZpyjNydyXZ6u6XuvuNJE8mObNvTSf53qqqJN+T5GtJLi90pwCwXsxHAFZmSsidTPLKnuvt3dv2+liSn0jyapLPJ/nt7v72/i9UVWerarOqNi9dunSVWwaAtbCw+ZiYkQDMMyXk6oDbet/1Lyf5bJIfTvKTST5WVd/3v/6j7vPdvdHdGydOnJi5VQBYKwubj4kZCcA8U0JuO8kte65vzs5PFvd6MMlTvWMryVeS3LGYLQLAWjIfAViZKSH3XJLbq+q23V/Qvi/JhX1rXk7ygSSpqh9K8u4kLy1yowCwZsxHAFbm+GELuvtyVT2c5Jkkx5I83t0Xq+qh3fvPJflIkieq6vPZeanJI939+hL3DQArZT4CsEqHhlySdPfTSZ7ed9u5PZ+/muSXFrs1AFhv5iMAqzLpDcEBAABYH0IOAABgMEIOAABgMEIOAABgMEIOAABgMEIOAABgMEIOAABgMEIOAABgMEIOAABgMEIOAABgMEIOAABgMEIOAABgMEIOAABgMEIOAABgMEIOAABgMEIOAABgMEIOAABgMEIOAABgMEIOAABgMEIOAABgMEIOAABgMEIOAABgMEIOAABgMEIOAABgMEIOAABgMEIOAABgMEIOAABgMEIOAABgMEIOAABgMEIOAABgMEIOAABgMEIOAABgMEIOAABgMEIOAABgMEIOAABgMEIOAABgMEIOAABgMEIOAABgMEIOAABgMEIOAABgMEIOAABgMEIOAABgMEIOAABgMEIOAABgMEIOAABgMJNCrqruqaoXq2qrqh69wpq7q+qzVXWxqv52sdsEgPVjPgKwKscPW1BVx5I8luT/JtlO8lxVXejuL+5Zc2OSjye5p7tfrqofXNJ+AWAtmI8ArNKUZ+TuSrLV3S919xtJnkxyZt+aDyV5qrtfTpLufm2x2wSAtWM+ArAyU0LuZJJX9lxv7962148neWdV/U1VPV9VDyxqgwCwpsxHAFbm0JdWJqkDbusDvs77knwgyXcl+fuqera7v/w/vlDV2SRnk+TWW2+dv1sAWB8Lm4+JGQnAPFOekdtOcsue65uTvHrAmk919ze6+/Ukn05y5/4v1N3nu3ujuzdOnDhxtXsGgHWwsPmYmJEAzDMl5J5LcntV3VZVNyS5L8mFfWv+PMnPVdXxqvruJD+d5EuL3SoArBXzEYCVOfSlld19uaoeTvJMkmNJHu/ui1X10O7957r7S1X1qSQvJPl2kk909xeWuXEAWCXzEYBVqu79L+e/PjY2Nnpzc3Ml3xuA66uqnu/ujVXvYxRmJMDRcC3zcdIbggMAALA+hBwAAMBghBwAAMBghBwAAMBghBwAAMBghBwAAMBghBwAAMBghBwAAMBghBwAAMBghBwAAMBghBwAAMBghBwAAMBghBwAAMBghBwAAMBghBwAAMBghBwAAMBghBwAAMBghBwAAMBghBwAAMBghBwAAMBghBwAAMBghBwAAMBghBwAAMBghBwAAMBghBwAAMBghBwAAMBghBwAAMBghBwAAMBghBwAAMBghBwAAMBghBwAAMBghBwAAMBghBwAAMBghBwAAMBghBwAAMBghBwAAMBghBwAAMBghBwAAMBghBwAAMBghBwAAMBghBwAAMBghBwAAMBghBwAAMBghBwAAMBghBwAAMBgJoVcVd1TVS9W1VZVPfoW636qqr5VVR9c3BYBYD2ZjwCsyqEhV1XHkjyW5HSSU0nur6pTV1j3B0meWfQmAWDdmI8ArNKUZ+TuSrLV3S919xtJnkxy5oB1v5XkT5O8tsD9AcC6Mh8BWJkpIXcyySt7rrd3b/tvVXUyya8kObe4rQHAWjMfAViZKSFXB9zW+67/KMkj3f2tt/xCVWerarOqNi9dujRxiwCwlhY2HxMzEoB5jk9Ys53klj3XNyd5dd+ajSRPVlWS3JTk3qq63N1/tndRd59Pcj5JNjY29g87ABjJwuZjYkYCMM+UkHsuye1VdVuSf0lyX5IP7V3Q3bf91+dV9USSvzxoSAHA24j5CMDKHBpy3X25qh7Ozl/bOpbk8e6+WFUP7d7vdf8AHDnmIwCrNOUZuXT300me3nfbgQOqu3/92rcFAOvPfARgVSa9ITgAAADrQ8gBAAAMRsgBAAAMRsgBAAAMRsgBAAAMRsgBAAAMRsgBAAAMRsgBAAAMRsgBAAAMRsgBAAAMRsgBAAAMRsgBAAAMRsgBAAAMRsgBAAAMRsgBAAAMRsgBAAAMRsgBAAAMRsgBAAAMRsgBAAAMRsgBAAAMRsgBAAAMRsgBAAAMRsgBAAAMRsgBAAAMRsgBAAAMRsgBAAAMRsgBAAAMRsgBAAAMRsgBAAAMRsgBAAAMRsgBAAAMRsgBAAAMRsgBAAAMRsgBAAAMRsgBAAAMRsgBAAAMRsgBAAAMRsgBAAAMRsgBAAAMRsgBAAAMRsgBAAAMRsgBAAAMRsgBAAAMRsgBAAAMRsgBAAAMRsgBAAAMZlLIVdU9VfViVW1V1aMH3P+rVfXC7sdnqurOxW8VANaL+QjAqhwaclV1LMljSU4nOZXk/qo6tW/ZV5L8fHe/J8lHkpxf9EYBYJ2YjwCs0pRn5O5KstXdL3X3G0meTHJm74Lu/kx3/9vu5bNJbl7sNgFg7ZiPAKzMlJA7meSVPdfbu7ddyW8k+auD7qiqs1W1WVWbly5dmr5LAFg/C5uPiRkJwDxTQq4OuK0PXFj1C9kZVI8cdH93n+/uje7eOHHixPRdAsD6Wdh8TMxIAOY5PmHNdpJb9lzfnOTV/Yuq6j1JPpHkdHf/62K2BwBry3wEYGWmPCP3XJLbq+q2qrohyX1JLuxdUFW3Jnkqya9195cXv00AWDvmIwArc+gzct19uaoeTvJMkmNJHu/ui1X10O7955L8bpIfSPLxqkqSy929sbxtA8BqmY8ArFJ1H/hy/qXb2Njozc3NlXxvAK6vqnpewExnRgIcDdcyHye9ITgAAADrQ8gBAAAMRsgBAAAMRsgBAAAMRsgBAAAMRsgBAAAMRsgBAAAMRsgBAAAMRsgBAAAMRsgBAAAMRsgBAAAMRsgBAAAMRsgBAAAMRsgBAAAMRsgBAAAMRsgBAAAMRsgBAAAMRsgBAAAMRsgBAAAMRsgBAAAMRsgBAAAMRsgBAAAMRsgBAAAMRsgBAAAMRsgBAAAMRsgBAAAMRsgBAAAMRsgBAAAMRsgBAAAMRsgBAAAMRsgBAAAMRsgBAAAMRsgBAAAMRsgBAAAMRsgBAAAMRsgBAAAMRsgBAAAMRsgBAAAMRsgBAAAMRsgBAAAMRsgBAAAMRsgBAAAMRsgBAAAMRsgBAAAMRsgBAAAMZlLIVdU9VfViVW1V1aMH3F9V9dHd+1+oqvcufqsAsF7MRwBW5dCQq6pjSR5LcjrJqST3V9WpfctOJ7l99+Nskj9e8D4BYK2YjwCs0pRn5O5KstXdL3X3G0meTHJm35ozST7ZO55NcmNVvWvBewWAdWI+ArAyU0LuZJJX9lxv7942dw0AvJ2YjwCszPEJa+qA2/oq1qSqzmbnpSVJ8h9V9YUJ358dNyV5fdWbGIjzmsd5zefM5nn3qjewBAubj4kZeY38e5zHec3jvOZxXvNc9XycEnLbSW7Zc31zklevYk26+3yS80lSVZvdvTFrt0eY85rHec3jvOZzZvNU1eaq97AEC5uPiRl5LZzXPM5rHuc1j/Oa51rm45SXVj6X5Paquq2qbkhyX5IL+9ZcSPLA7l/nen+Sr3f3V692UwAwAPMRgJU59Bm57r5cVQ8neSbJsSSPd/fFqnpo9/5zSZ5Ocm+SrSTfTPLg8rYMAKtnPgKwSlNeWpnufjo7w2jvbef2fN5JPjzze5+fuf6oc17zOK95nNd8zmyet+V5LWk+Jm/T81oi5zWP85rHec3jvOa56vOqnRkDAADAKKb8jhwAAABrZOkhV1X3VNWLVbVVVY8ecH9V1Ud373+hqt677D2tswnn9au75/RCVX2mqu5cxT7XxWHntWfdT1XVt6rqg9dzf+tmynlV1d1V9dmqulhVf3u997hOJvx7/P6q+ouq+tzueR3p33+qqser6rUr/dl8j/f/k/k4j/k4nxk5jxk5jxk53dLmY3cv7SM7v/z9T0l+NMkNST6X5NS+Nfcm+avsvNfO+5P8wzL3tM4fE8/rZ5K8c/fz087rrc9rz7q/zs7vsXxw1fte5/NKcmOSLya5dff6B1e97zU/r99J8ge7n59I8rUkN6x67ys8s/+T5L1JvnCF+z3ev3kW5uPiz8t8nHlme9aZkWbkMs7LjHzzLJYyH5f9jNxdSba6+6XufiPJk0nO7FtzJskne8ezSW6sqncteV/r6tDz6u7PdPe/7V4+m533JDqqpvz/lSS/leRPk7x2PTe3hqac14eSPNXdLydJdx/lM5tyXp3ke6uqknxPdobU5eu7zfXR3Z/Ozhlcicf7N5mP85iP85mR85iR85iRMyxrPi475E4meWXP9fbubXPXHBVzz+I3slPvR9Wh51VVJ5P8SpJzYcr/Xz+e5J1V9TdV9XxVPXDddrd+ppzXx5L8RHbe4PnzSX67u799fbY3JI/3bzIf5zEf5zMj5zEj5zEjF+uqHu8nvf3ANagDbtv/ZzKnrDkqJp9FVf1CdgbVzy51R+ttynn9UZJHuvtbOz8QOtKmnNfxJO9L8oEk35Xk76vq2e7+8rI3t4amnNcvJ/lskl9M8mNJ/n9V/V13//uS9zYqj/dvMh/nMR/nMyPnMSPnMSMX66oe75cdcttJbtlzfXN2qnzumqNi0llU1XuSfCLJ6e7+1+u0t3U05bw2kjy5O6BuSnJvVV3u7j+7LjtcL1P/Pb7e3d9I8o2q+nSSO5McxSE15bweTPL7vfMC962q+kqSO5L84/XZ4nA83r/JfJzHfJzPjJzHjJzHjFysq3q8X/ZLK59LcntV3VZVNyS5L8mFfWsuJHlg96+1vD/J17v7q0ve17o69Lyq6tYkTyX5tSP6E6C9Dj2v7r6tu3+ku38kyf9L8ptHdEAl0/49/nmSn6uq41X13Ul+OsmXrvM+18WU83o5Oz+ZTVX9UJJ3J3npuu5yLB7v32Q+zmM+zmdGzmNGzmNGLtZVPd4v9Rm57r5cVQ8neSY7f93m8e6+WFUP7d5/Ljt/JeneJFtJvpmdej+SJp7X7yb5gSQf3/0J2uXu3ljVnldp4nmxa8p5dfeXqupTSV5I8u0kn+juA/9U7tvdxP+/PpLkiar6fHZeFvFId7++sk2vWFX9SZK7k9xUVdtJfi/JdyYe7/czH+cxH+czI+cxI+cxI+dZ1nysnWc7AQAAGMXS3xAcAACAxRJyAAAAgxFyAAAAgxFyAAAAgxFyAAAAgxFyAAAAgxFyAAAAgxFyAAAAg/lPvRNY/QUO71YAAAAASUVORK5CYII=\n",
      "text/plain": [
       "<Figure size 1080x360 with 2 Axes>"
      ]
     },
     "metadata": {
      "needs_background": "light"
     },
     "output_type": "display_data"
    }
   ],
   "source": [
    "fig, ax = plt.subplots(1,2, figsize=(15,5))\n",
    "sns.countplot(y_train.ravel(), ax=ax[0], palette = ['#7DB0BB'])\n",
    "sns.countplot(y_test.ravel(), ax=ax[1], palette = ['#AE95C1'])\n",
    "ax[0].set_title('Count of Train set labels')\n",
    "ax[1].set_title('Count of Test set labels')\n",
    "plt.show()"
   ]
  },
  {
   "cell_type": "code",
   "execution_count": 32,
   "id": "ec02355f",
   "metadata": {},
   "outputs": [],
   "source": [
    "classes = ['airplane', 'automobile', 'bird', 'cat', 'deer', 'dog', 'frog', 'horse', 'ship', 'truck']"
   ]
  },
  {
   "cell_type": "code",
   "execution_count": null,
   "id": "3bcaa825",
   "metadata": {},
   "outputs": [
    {
     "name": "stderr",
     "output_type": "stream",
     "text": [
      "ERROR:root:Internal Python error in the inspect module.\n",
      "Below is the traceback from this internal error.\n",
      "\n",
      "ERROR:root:Internal Python error in the inspect module.\n",
      "Below is the traceback from this internal error.\n",
      "\n",
      "ERROR:root:Internal Python error in the inspect module.\n",
      "Below is the traceback from this internal error.\n",
      "\n"
     ]
    },
    {
     "name": "stdout",
     "output_type": "stream",
     "text": [
      "ERROR! Session/line number was not unique in database. History logging moved to new session 330\n",
      "Traceback (most recent call last):\n",
      "  File \"C:\\Users\\29459\\anaconda3\\envs\\python37\\lib\\site-packages\\IPython\\core\\interactiveshell.py\", line 3437, in run_code\n",
      "    exec(code_obj, self.user_global_ns, self.user_ns)\n",
      "  File \"<ipython-input-49-808017229d47>\", line 7, in <module>\n",
      "    show_img(X_train, y_train, 30)\n",
      "  File \"<ipython-input-49-808017229d47>\", line 3, in show_img\n",
      "    plt.imshow(X[index])\n",
      "  File \"C:\\Users\\29459\\anaconda3\\envs\\python37\\lib\\site-packages\\matplotlib\\pyplot.py\", line 2730, in imshow\n",
      "    **kwargs)\n",
      "  File \"C:\\Users\\29459\\anaconda3\\envs\\python37\\lib\\site-packages\\matplotlib\\__init__.py\", line 1447, in inner\n",
      "    return func(ax, *map(sanitize_sequence, args), **kwargs)\n",
      "  File \"C:\\Users\\29459\\anaconda3\\envs\\python37\\lib\\site-packages\\matplotlib\\axes\\_axes.py\", line 5523, in imshow\n",
      "    im.set_data(X)\n",
      "  File \"C:\\Users\\29459\\anaconda3\\envs\\python37\\lib\\site-packages\\matplotlib\\image.py\", line 712, in set_data\n",
      "    .format(self._A.shape))\n",
      "TypeError: Invalid shape (3072,) for image data\n",
      "\n",
      "During handling of the above exception, another exception occurred:\n",
      "\n",
      "Traceback (most recent call last):\n",
      "  File \"C:\\Users\\29459\\anaconda3\\envs\\python37\\lib\\site-packages\\IPython\\core\\interactiveshell.py\", line 2061, in showtraceback\n",
      "    stb = value._render_traceback_()\n",
      "AttributeError: 'TypeError' object has no attribute '_render_traceback_'\n",
      "\n",
      "During handling of the above exception, another exception occurred:\n",
      "\n",
      "Traceback (most recent call last):\n",
      "  File \"C:\\Users\\29459\\anaconda3\\envs\\python37\\lib\\site-packages\\IPython\\core\\ultratb.py\", line 1101, in get_records\n",
      "    return _fixed_getinnerframes(etb, number_of_lines_of_context, tb_offset)\n",
      "  File \"C:\\Users\\29459\\anaconda3\\envs\\python37\\lib\\site-packages\\IPython\\core\\ultratb.py\", line 248, in wrapped\n",
      "    return f(*args, **kwargs)\n",
      "  File \"C:\\Users\\29459\\anaconda3\\envs\\python37\\lib\\site-packages\\IPython\\core\\ultratb.py\", line 281, in _fixed_getinnerframes\n",
      "    records = fix_frame_records_filenames(inspect.getinnerframes(etb, context))\n",
      "  File \"C:\\Users\\29459\\anaconda3\\envs\\python37\\lib\\inspect.py\", line 1502, in getinnerframes\n",
      "    frameinfo = (tb.tb_frame,) + getframeinfo(tb, context)\n",
      "  File \"C:\\Users\\29459\\anaconda3\\envs\\python37\\lib\\inspect.py\", line 1460, in getframeinfo\n",
      "    filename = getsourcefile(frame) or getfile(frame)\n",
      "  File \"C:\\Users\\29459\\anaconda3\\envs\\python37\\lib\\inspect.py\", line 696, in getsourcefile\n",
      "    if getattr(getmodule(object, filename), '__loader__', None) is not None:\n",
      "  File \"C:\\Users\\29459\\anaconda3\\envs\\python37\\lib\\inspect.py\", line 733, in getmodule\n",
      "    if ismodule(module) and hasattr(module, '__file__'):\n",
      "  File \"C:\\Users\\29459\\anaconda3\\envs\\python37\\lib\\site-packages\\tensorflow\\__init__.py\", line 50, in __getattr__\n",
      "    module = self._load()\n",
      "  File \"C:\\Users\\29459\\anaconda3\\envs\\python37\\lib\\site-packages\\tensorflow\\__init__.py\", line 44, in _load\n",
      "    module = _importlib.import_module(self.__name__)\n",
      "  File \"C:\\Users\\29459\\anaconda3\\envs\\python37\\lib\\importlib\\__init__.py\", line 127, in import_module\n",
      "    return _bootstrap._gcd_import(name[level:], package, level)\n",
      "  File \"<frozen importlib._bootstrap>\", line 1006, in _gcd_import\n",
      "  File \"<frozen importlib._bootstrap>\", line 983, in _find_and_load\n",
      "  File \"<frozen importlib._bootstrap>\", line 965, in _find_and_load_unlocked\n",
      "ModuleNotFoundError: No module named 'tensorflow_core.estimator'\n",
      "Traceback (most recent call last):\n",
      "  File \"C:\\Users\\29459\\anaconda3\\envs\\python37\\lib\\site-packages\\IPython\\core\\interactiveshell.py\", line 3437, in run_code\n",
      "    exec(code_obj, self.user_global_ns, self.user_ns)\n",
      "  File \"<ipython-input-49-808017229d47>\", line 7, in <module>\n",
      "    show_img(X_train, y_train, 30)\n",
      "  File \"<ipython-input-49-808017229d47>\", line 3, in show_img\n",
      "    plt.imshow(X[index])\n",
      "  File \"C:\\Users\\29459\\anaconda3\\envs\\python37\\lib\\site-packages\\matplotlib\\pyplot.py\", line 2730, in imshow\n",
      "    **kwargs)\n",
      "  File \"C:\\Users\\29459\\anaconda3\\envs\\python37\\lib\\site-packages\\matplotlib\\__init__.py\", line 1447, in inner\n",
      "    return func(ax, *map(sanitize_sequence, args), **kwargs)\n",
      "  File \"C:\\Users\\29459\\anaconda3\\envs\\python37\\lib\\site-packages\\matplotlib\\axes\\_axes.py\", line 5523, in imshow\n",
      "    im.set_data(X)\n",
      "  File \"C:\\Users\\29459\\anaconda3\\envs\\python37\\lib\\site-packages\\matplotlib\\image.py\", line 712, in set_data\n",
      "    .format(self._A.shape))\n",
      "TypeError: Invalid shape (3072,) for image data\n",
      "\n",
      "During handling of the above exception, another exception occurred:\n",
      "\n",
      "Traceback (most recent call last):\n",
      "  File \"C:\\Users\\29459\\anaconda3\\envs\\python37\\lib\\site-packages\\IPython\\core\\interactiveshell.py\", line 2061, in showtraceback\n",
      "    stb = value._render_traceback_()\n",
      "AttributeError: 'TypeError' object has no attribute '_render_traceback_'\n",
      "\n",
      "During handling of the above exception, another exception occurred:\n",
      "\n",
      "Traceback (most recent call last):\n",
      "  File \"C:\\Users\\29459\\anaconda3\\envs\\python37\\lib\\site-packages\\IPython\\core\\interactiveshell.py\", line 3357, in run_ast_nodes\n",
      "    if (await self.run_code(code, result,  async_=asy)):\n",
      "  File \"C:\\Users\\29459\\anaconda3\\envs\\python37\\lib\\site-packages\\IPython\\core\\interactiveshell.py\", line 3454, in run_code\n",
      "    self.showtraceback(running_compiled_code=True)\n",
      "  File \"C:\\Users\\29459\\anaconda3\\envs\\python37\\lib\\site-packages\\IPython\\core\\interactiveshell.py\", line 2064, in showtraceback\n",
      "    value, tb, tb_offset=tb_offset)\n",
      "  File \"C:\\Users\\29459\\anaconda3\\envs\\python37\\lib\\site-packages\\IPython\\core\\ultratb.py\", line 1368, in structured_traceback\n",
      "    self, etype, value, tb, tb_offset, number_of_lines_of_context)\n",
      "  File \"C:\\Users\\29459\\anaconda3\\envs\\python37\\lib\\site-packages\\IPython\\core\\ultratb.py\", line 1268, in structured_traceback\n",
      "    self, etype, value, tb, tb_offset, number_of_lines_of_context\n",
      "  File \"C:\\Users\\29459\\anaconda3\\envs\\python37\\lib\\site-packages\\IPython\\core\\ultratb.py\", line 1125, in structured_traceback\n",
      "    tb_offset)\n",
      "  File \"C:\\Users\\29459\\anaconda3\\envs\\python37\\lib\\site-packages\\IPython\\core\\ultratb.py\", line 1082, in format_exception_as_a_whole\n",
      "    last_unique, recursion_repeat = find_recursion(orig_etype, evalue, records)\n",
      "  File \"C:\\Users\\29459\\anaconda3\\envs\\python37\\lib\\site-packages\\IPython\\core\\ultratb.py\", line 382, in find_recursion\n",
      "    return len(records), 0\n",
      "TypeError: object of type 'NoneType' has no len()\n",
      "\n",
      "During handling of the above exception, another exception occurred:\n",
      "\n",
      "Traceback (most recent call last):\n",
      "  File \"C:\\Users\\29459\\anaconda3\\envs\\python37\\lib\\site-packages\\IPython\\core\\interactiveshell.py\", line 2061, in showtraceback\n",
      "    stb = value._render_traceback_()\n",
      "AttributeError: 'TypeError' object has no attribute '_render_traceback_'\n",
      "\n",
      "During handling of the above exception, another exception occurred:\n",
      "\n",
      "Traceback (most recent call last):\n",
      "  File \"C:\\Users\\29459\\anaconda3\\envs\\python37\\lib\\site-packages\\IPython\\core\\ultratb.py\", line 1101, in get_records\n",
      "    return _fixed_getinnerframes(etb, number_of_lines_of_context, tb_offset)\n",
      "  File \"C:\\Users\\29459\\anaconda3\\envs\\python37\\lib\\site-packages\\IPython\\core\\ultratb.py\", line 248, in wrapped\n",
      "    return f(*args, **kwargs)\n",
      "  File \"C:\\Users\\29459\\anaconda3\\envs\\python37\\lib\\site-packages\\IPython\\core\\ultratb.py\", line 281, in _fixed_getinnerframes\n",
      "    records = fix_frame_records_filenames(inspect.getinnerframes(etb, context))\n",
      "  File \"C:\\Users\\29459\\anaconda3\\envs\\python37\\lib\\inspect.py\", line 1502, in getinnerframes\n",
      "    frameinfo = (tb.tb_frame,) + getframeinfo(tb, context)\n",
      "  File \"C:\\Users\\29459\\anaconda3\\envs\\python37\\lib\\inspect.py\", line 1460, in getframeinfo\n",
      "    filename = getsourcefile(frame) or getfile(frame)\n",
      "  File \"C:\\Users\\29459\\anaconda3\\envs\\python37\\lib\\inspect.py\", line 696, in getsourcefile\n",
      "    if getattr(getmodule(object, filename), '__loader__', None) is not None:\n",
      "  File \"C:\\Users\\29459\\anaconda3\\envs\\python37\\lib\\inspect.py\", line 733, in getmodule\n",
      "    if ismodule(module) and hasattr(module, '__file__'):\n",
      "  File \"C:\\Users\\29459\\anaconda3\\envs\\python37\\lib\\site-packages\\tensorflow\\__init__.py\", line 50, in __getattr__\n",
      "    module = self._load()\n",
      "  File \"C:\\Users\\29459\\anaconda3\\envs\\python37\\lib\\site-packages\\tensorflow\\__init__.py\", line 44, in _load\n",
      "    module = _importlib.import_module(self.__name__)\n",
      "  File \"C:\\Users\\29459\\anaconda3\\envs\\python37\\lib\\importlib\\__init__.py\", line 127, in import_module\n",
      "    return _bootstrap._gcd_import(name[level:], package, level)\n",
      "  File \"<frozen importlib._bootstrap>\", line 1006, in _gcd_import\n",
      "  File \"<frozen importlib._bootstrap>\", line 983, in _find_and_load\n",
      "  File \"<frozen importlib._bootstrap>\", line 965, in _find_and_load_unlocked\n",
      "ModuleNotFoundError: No module named 'tensorflow_core.estimator'\n",
      "Traceback (most recent call last):\n",
      "  File \"C:\\Users\\29459\\anaconda3\\envs\\python37\\lib\\site-packages\\IPython\\core\\interactiveshell.py\", line 3437, in run_code\n",
      "    exec(code_obj, self.user_global_ns, self.user_ns)\n",
      "  File \"<ipython-input-49-808017229d47>\", line 7, in <module>\n",
      "    show_img(X_train, y_train, 30)\n",
      "  File \"<ipython-input-49-808017229d47>\", line 3, in show_img\n",
      "    plt.imshow(X[index])\n",
      "  File \"C:\\Users\\29459\\anaconda3\\envs\\python37\\lib\\site-packages\\matplotlib\\pyplot.py\", line 2730, in imshow\n",
      "    **kwargs)\n",
      "  File \"C:\\Users\\29459\\anaconda3\\envs\\python37\\lib\\site-packages\\matplotlib\\__init__.py\", line 1447, in inner\n",
      "    return func(ax, *map(sanitize_sequence, args), **kwargs)\n",
      "  File \"C:\\Users\\29459\\anaconda3\\envs\\python37\\lib\\site-packages\\matplotlib\\axes\\_axes.py\", line 5523, in imshow\n",
      "    im.set_data(X)\n",
      "  File \"C:\\Users\\29459\\anaconda3\\envs\\python37\\lib\\site-packages\\matplotlib\\image.py\", line 712, in set_data\n",
      "    .format(self._A.shape))\n",
      "TypeError: Invalid shape (3072,) for image data\n",
      "\n",
      "During handling of the above exception, another exception occurred:\n",
      "\n",
      "Traceback (most recent call last):\n",
      "  File \"C:\\Users\\29459\\anaconda3\\envs\\python37\\lib\\site-packages\\IPython\\core\\interactiveshell.py\", line 2061, in showtraceback\n",
      "    stb = value._render_traceback_()\n",
      "AttributeError: 'TypeError' object has no attribute '_render_traceback_'\n",
      "\n",
      "During handling of the above exception, another exception occurred:\n",
      "\n",
      "Traceback (most recent call last):\n",
      "  File \"C:\\Users\\29459\\anaconda3\\envs\\python37\\lib\\site-packages\\IPython\\core\\interactiveshell.py\", line 3357, in run_ast_nodes\n",
      "    if (await self.run_code(code, result,  async_=asy)):\n",
      "  File \"C:\\Users\\29459\\anaconda3\\envs\\python37\\lib\\site-packages\\IPython\\core\\interactiveshell.py\", line 3454, in run_code\n",
      "    self.showtraceback(running_compiled_code=True)\n",
      "  File \"C:\\Users\\29459\\anaconda3\\envs\\python37\\lib\\site-packages\\IPython\\core\\interactiveshell.py\", line 2064, in showtraceback\n",
      "    value, tb, tb_offset=tb_offset)\n",
      "  File \"C:\\Users\\29459\\anaconda3\\envs\\python37\\lib\\site-packages\\IPython\\core\\ultratb.py\", line 1368, in structured_traceback\n",
      "    self, etype, value, tb, tb_offset, number_of_lines_of_context)\n",
      "  File \"C:\\Users\\29459\\anaconda3\\envs\\python37\\lib\\site-packages\\IPython\\core\\ultratb.py\", line 1268, in structured_traceback\n",
      "    self, etype, value, tb, tb_offset, number_of_lines_of_context\n",
      "  File \"C:\\Users\\29459\\anaconda3\\envs\\python37\\lib\\site-packages\\IPython\\core\\ultratb.py\", line 1125, in structured_traceback\n",
      "    tb_offset)\n",
      "  File \"C:\\Users\\29459\\anaconda3\\envs\\python37\\lib\\site-packages\\IPython\\core\\ultratb.py\", line 1082, in format_exception_as_a_whole\n",
      "    last_unique, recursion_repeat = find_recursion(orig_etype, evalue, records)\n",
      "  File \"C:\\Users\\29459\\anaconda3\\envs\\python37\\lib\\site-packages\\IPython\\core\\ultratb.py\", line 382, in find_recursion\n",
      "    return len(records), 0\n",
      "TypeError: object of type 'NoneType' has no len()\n",
      "\n",
      "During handling of the above exception, another exception occurred:\n",
      "\n",
      "Traceback (most recent call last):\n",
      "  File \"C:\\Users\\29459\\anaconda3\\envs\\python37\\lib\\site-packages\\IPython\\core\\interactiveshell.py\", line 2061, in showtraceback\n",
      "    stb = value._render_traceback_()\n",
      "AttributeError: 'TypeError' object has no attribute '_render_traceback_'\n",
      "\n",
      "During handling of the above exception, another exception occurred:\n",
      "\n",
      "Traceback (most recent call last):\n",
      "  File \"C:\\Users\\29459\\anaconda3\\envs\\python37\\lib\\site-packages\\IPython\\core\\interactiveshell.py\", line 2940, in _run_cell\n",
      "    return runner(coro)\n",
      "  File \"C:\\Users\\29459\\anaconda3\\envs\\python37\\lib\\site-packages\\IPython\\core\\async_helpers.py\", line 68, in _pseudo_sync_runner\n",
      "    coro.send(None)\n",
      "  File \"C:\\Users\\29459\\anaconda3\\envs\\python37\\lib\\site-packages\\IPython\\core\\interactiveshell.py\", line 3166, in run_cell_async\n",
      "    interactivity=interactivity, compiler=compiler, result=result)\n",
      "  File \"C:\\Users\\29459\\anaconda3\\envs\\python37\\lib\\site-packages\\IPython\\core\\interactiveshell.py\", line 3376, in run_ast_nodes\n",
      "    self.showtraceback()\n",
      "  File \"C:\\Users\\29459\\anaconda3\\envs\\python37\\lib\\site-packages\\IPython\\core\\interactiveshell.py\", line 2064, in showtraceback\n",
      "    value, tb, tb_offset=tb_offset)\n",
      "  File \"C:\\Users\\29459\\anaconda3\\envs\\python37\\lib\\site-packages\\IPython\\core\\ultratb.py\", line 1368, in structured_traceback\n",
      "    self, etype, value, tb, tb_offset, number_of_lines_of_context)\n",
      "  File \"C:\\Users\\29459\\anaconda3\\envs\\python37\\lib\\site-packages\\IPython\\core\\ultratb.py\", line 1268, in structured_traceback\n",
      "    self, etype, value, tb, tb_offset, number_of_lines_of_context\n",
      "  File \"C:\\Users\\29459\\anaconda3\\envs\\python37\\lib\\site-packages\\IPython\\core\\ultratb.py\", line 1143, in structured_traceback\n",
      "    chained_exceptions_tb_offset)\n",
      "  File \"C:\\Users\\29459\\anaconda3\\envs\\python37\\lib\\site-packages\\IPython\\core\\ultratb.py\", line 1082, in format_exception_as_a_whole\n",
      "    last_unique, recursion_repeat = find_recursion(orig_etype, evalue, records)\n",
      "  File \"C:\\Users\\29459\\anaconda3\\envs\\python37\\lib\\site-packages\\IPython\\core\\ultratb.py\", line 382, in find_recursion\n",
      "    return len(records), 0\n",
      "TypeError: object of type 'NoneType' has no len()\n",
      "\n",
      "During handling of the above exception, another exception occurred:\n",
      "\n",
      "Traceback (most recent call last):\n",
      "  File \"C:\\Users\\29459\\anaconda3\\envs\\python37\\lib\\site-packages\\IPython\\core\\interactiveshell.py\", line 2061, in showtraceback\n",
      "    stb = value._render_traceback_()\n",
      "AttributeError: 'TypeError' object has no attribute '_render_traceback_'\n",
      "\n",
      "During handling of the above exception, another exception occurred:\n",
      "\n",
      "Traceback (most recent call last):\n",
      "  File \"C:\\Users\\29459\\anaconda3\\envs\\python37\\lib\\site-packages\\IPython\\core\\ultratb.py\", line 1101, in get_records\n",
      "    return _fixed_getinnerframes(etb, number_of_lines_of_context, tb_offset)\n",
      "  File \"C:\\Users\\29459\\anaconda3\\envs\\python37\\lib\\site-packages\\IPython\\core\\ultratb.py\", line 248, in wrapped\n",
      "    return f(*args, **kwargs)\n",
      "  File \"C:\\Users\\29459\\anaconda3\\envs\\python37\\lib\\site-packages\\IPython\\core\\ultratb.py\", line 281, in _fixed_getinnerframes\n",
      "    records = fix_frame_records_filenames(inspect.getinnerframes(etb, context))\n",
      "  File \"C:\\Users\\29459\\anaconda3\\envs\\python37\\lib\\inspect.py\", line 1502, in getinnerframes\n",
      "    frameinfo = (tb.tb_frame,) + getframeinfo(tb, context)\n",
      "  File \"C:\\Users\\29459\\anaconda3\\envs\\python37\\lib\\inspect.py\", line 1460, in getframeinfo\n",
      "    filename = getsourcefile(frame) or getfile(frame)\n",
      "  File \"C:\\Users\\29459\\anaconda3\\envs\\python37\\lib\\inspect.py\", line 696, in getsourcefile\n",
      "    if getattr(getmodule(object, filename), '__loader__', None) is not None:\n",
      "  File \"C:\\Users\\29459\\anaconda3\\envs\\python37\\lib\\inspect.py\", line 733, in getmodule\n",
      "    if ismodule(module) and hasattr(module, '__file__'):\n",
      "  File \"C:\\Users\\29459\\anaconda3\\envs\\python37\\lib\\site-packages\\tensorflow\\__init__.py\", line 50, in __getattr__\n",
      "    module = self._load()\n",
      "  File \"C:\\Users\\29459\\anaconda3\\envs\\python37\\lib\\site-packages\\tensorflow\\__init__.py\", line 44, in _load\n",
      "    module = _importlib.import_module(self.__name__)\n",
      "  File \"C:\\Users\\29459\\anaconda3\\envs\\python37\\lib\\importlib\\__init__.py\", line 127, in import_module\n",
      "    return _bootstrap._gcd_import(name[level:], package, level)\n",
      "  File \"<frozen importlib._bootstrap>\", line 1006, in _gcd_import\n",
      "  File \"<frozen importlib._bootstrap>\", line 983, in _find_and_load\n",
      "  File \"<frozen importlib._bootstrap>\", line 965, in _find_and_load_unlocked\n",
      "ModuleNotFoundError: No module named 'tensorflow_core.estimator'\n"
     ]
    },
    {
     "data": {
      "image/png": "iVBORw0KGgoAAAANSUhEUgAAAJoAAACQCAYAAADwZHJxAAAAOXRFWHRTb2Z0d2FyZQBNYXRwbG90bGliIHZlcnNpb24zLjMuNCwgaHR0cHM6Ly9tYXRwbG90bGliLm9yZy8QVMy6AAAACXBIWXMAAAsTAAALEwEAmpwYAAAHGUlEQVR4nO3dX4hc9RnG8e9TE6FN/6R0o1XbFAupMYJK3NoUbJtS2sa9CYIX/qHBICyKLV62V3rhlReCiNWwSAje6E3F2hLtnebCprhbkhgVZas0bhWSqET8g2X19eKchMlms3t29jfv5px5PjCwM+fMmffseZjZ2d95z08RgdmgfWWlC7Dh4KBZCgfNUjholsJBsxQOmqVYNGiSdks6KunwWZZL0kOSpiUdkrS5fJnWdk3e0fYA2xZYfj2wob6NA48uvyzrmkWDFhH7gPcXWGU78HhU9gNrJV1UqkDrhhJ/o10CvN1zf6Z+zOyUVQW2oXkem3dcS9I41ccra9asuWbjxo0FXt6yTE1NHY+Idf08t0TQZoDv99z/HvDOfCtGxAQwATA6OhqTk5MFXt6ySPpvv88t8dH5DLCj/va5BTgREe8W2K51yKLvaJKeALYCI5JmgHuB1QARsQvYC4wB08AnwM5BFWvttWjQIuLmRZYHcFexiqyTPDJgKRw0S+GgWQoHzVI4aJbCQbMUDpqlcNAshYNmKRw0S+GgWQoHzVI4aJaiUdAkbZP0et3p9Kd5ln9L0t8kHZT0iiSfKmSnadJudx7wZ6pup03AzZI2zVntLuDViLiK6ty1BySdX7hWa7Em72jXAtMR8WZE/B94kqrzqVcA35Ak4OtUXVOzRSu1VmsStCZdTg8Dl1P1CrwM3B0RXxSp0DqhSdCadDn9FjgAXAxcDTws6ZtnbEgalzQpafLYsWNLLNXarEnQmnQ57QSeqpuIp4G3gDN66SJiIiJGI2J03bq+uraspZoE7SVgg6RL6z/wb6LqfOp1BPgVgKQLgcuAN0sWau3WpDllVtLvgX8A5wG7I+IVSXfUy3cB9wF7JL1M9VH7x4g4PsC6rWUaNRBHxF6qtrrex3b1/PwO8JuypVmXeGTAUjholsJBsxQOmqVw0CyFg2YpHDRL4aBZCgfNUjholsJBsxQOmqVw0CxFkS6oep2tkg7UXVAvlC3T2q7JVblPdkH9mups25ckPRMRr/assxZ4BNgWEUckXTCgeq2lSnVB3UJ1KvcRgIg4WrZMa7tSXVA/Ar4t6XlJU5J2lCrQuqHJGbZNuqBWAddQ9Q18FfinpP0R8cZpG+qZC2r9+vVLr9Zaq1QX1AzwXER8XPcK7AOumrshd0ENr1JdUH8FfiZplaSvAT8BXitbqrVZkS6oiHhN0nPAIeAL4LGImHdqbBtOqqZyyudpFNtH0lREjPbzXI8MWAoHzVI4aJbCQbMUDpqlcNAshYNmKRw0S+GgWQoHzVI4aJbCQbMUxZpT6vV+LOlzSTeWK9G6oNQUPSfXu5/qdCKz05RqTgH4A/AXwI0pdoYizSmSLgFuAHZhNo9SU/Q8SDW3wOcLbshT9AytJl1QTZpTRoEnq8ntGAHGJM1GxNO9K0XEBDAB1Rm2fdZsLdQkaKeaU4D/UTWn3NK7QkRcevJnSXuAv88NmQ23UlP0mC2oyBQ9cx6/bfllWdd4ZMBSOGiWwkGzFA6apXDQLIWDZikcNEvhoFkKB81SOGiWwkGzFA6apXDQLEWRLihJt0o6VN9elHTGFbltuJXqgnoL+EVEXAncR30WrdlJRbqgIuLFiPigvruf6nRvs1NKTdHT63bg2eUUZd1TaoqeakXpl1RBu+4syz1Fz5AqNUUPkq4EHgO2R8R7823IU/QMryJT9EhaDzwF/G7uRGNmUK4L6h7gO8AjdW/nbL8zbFg3eYoea8xT9Ng5z0GzFA6apXDQLIWDZikcNEvhoFkKB81SOGiWwkGzFA6apXDQLIWDZilKdUFJ0kP18kOSNpcv1dqsVBfU9cCG+jYOPFq4Tmu5UnNBbQcej8p+YK2kiwrXai1WqgtqqZ1SNmRKdUE16pTq7YICPpN0uMHrt9EIcHylixiAy/p9Yqm5oBp1SvXOBSVpsqt9BV3dN0l9n3tfpAuqvr+j/va5BTgREe/2W5R1T6kuqL3AGDANfALsHFzJ1kYr1gUlabz+KO2cru7bcvZrxYJmw8VDUJZi4EHr6vBVg/3aKumEpAP17Z6VqHOpJO2WdPRs/3rq+3hFxMBuVF8e/gP8EDgfOAhsmrPOGNVlrgRsAf41yJoS92sr1UzMK17vEvft58Bm4PBZlvd1vAb9jtbV4asm+9VKEbEPeH+BVfo6XoMOWleHr5rW/FNJByU9K+mKnNIGrq/j1Wiq62UoNnx1jmlS87+BH0TER5LGgKepzm5pu76O16Df0YoNX51jFq05Ij6MiI/qn/cCqyWN5JU4MH0dr0EHravDV00uTvhd1ReLk3Qt1e963ithtkxfx2ugH53R0eGrhvt1I3CnpFngU+CmiHP/v+OSnqD6xjwiaQa4F1gNyzteHhmwFB4ZsBQOmqVw0CyFg2YpHDRL4aBZCgfNUjholuJLrudSHH2avdsAAAAASUVORK5CYII=\n",
      "text/plain": [
       "<Figure size 144x144 with 1 Axes>"
      ]
     },
     "metadata": {
      "needs_background": "light"
     },
     "output_type": "display_data"
    }
   ],
   "source": [
    "def show_img(X, y, index):\n",
    "    plt.figure(figsize=(2,2))\n",
    "    plt.imshow(X[index])\n",
    "    plt.xlabel(classes[y[index]])\n",
    "    plt.show()\n",
    "\n",
    "show_img(X_train, y_train, 30)"
   ]
  },
  {
   "cell_type": "code",
   "execution_count": 35,
   "id": "792ecc0d",
   "metadata": {},
   "outputs": [],
   "source": [
    "for i in range(1, 6):\n",
    "    feats, lbls = load_batch('data', i)\n",
    "    test_size = int(len(feats) * 0.1)\n",
    "    \n",
    "    # training data\n",
    "    norm_feats = normalize(feats[:-test_size])\n",
    "    one_hot_lbls = one_hot_encode(lbls[:-test_size])\n",
    "    pickle.dump((norm_feats, one_hot_lbls), open('preprocess_batch_%i.p' % i, 'wb'))\n",
    "    \n",
    "    # add the rest to the test data\n",
    "    test_feats.extend(feats[-test_size:])\n",
    "    test_lbls.extend(lbls[-test_size:])\n",
    "\n",
    "# dump the test data too\n",
    "norm_test_feats = normalize(np.array(test_feats))\n",
    "one_hot_test_lbls = one_hot_encode(np.array(test_lbls))\n",
    "pickle.dump((norm_test_feats, one_hot_test_lbls), open('preprocess_test.p', 'wb'))\n"
   ]
  },
  {
   "cell_type": "code",
   "execution_count": 36,
   "id": "cc66d39e",
   "metadata": {},
   "outputs": [],
   "source": [
    "def conv2d_maxpool(x_tensor, conv_num_outputs, conv_ksize, conv_strides, pool_ksize, pool_strides):\n",
    "    \"\"\"\n",
    "    Apply convolution then max pooling to x_tensor\n",
    "    :param x_tensor: TensorFlow Tensor\n",
    "    :param conv_num_outputs: Number of outputs for the convolutional layer\n",
    "    :param conv_ksize: kernal size 2-D Tuple for the convolutional layer\n",
    "    :param conv_strides: Stride 2-D Tuple for convolution\n",
    "    :param pool_ksize: kernal size 2-D Tuple for pool\n",
    "    :param pool_strides: Stride 2-D Tuple for pool\n",
    "    : return: A tensor that represents convolution and max pooling of x_tensor\n",
    "    \"\"\"\n",
    "    # Weights\n",
    "    W_shape = list(conv_ksize) + [int(x_tensor.shape[3]), conv_num_outputs]\n",
    "    W = tf.Variable(tf.truncated_normal(W_shape, stddev=.05))\n",
    "    \n",
    "    # Apply convolution\n",
    "    x = tf.nn.conv2d(\n",
    "        x_tensor, W,\n",
    "        strides = [1] + list(conv_strides) + [1],\n",
    "        padding = 'SAME'\n",
    "    )\n",
    "    \n",
    "    # Add bias\n",
    "    b = tf.Variable(tf.zeros([conv_num_outputs]))\n",
    "    x = tf.nn.bias_add(x, b)\n",
    "    \n",
    "    # Nonlinear activation (ReLU)\n",
    "    x = tf.nn.relu(x)\n",
    "    \n",
    "    # Max pooling\n",
    "    return tf.nn.max_pool(\n",
    "        x,\n",
    "        ksize = [1] + list(pool_ksize) + [1],\n",
    "        strides = [1] + list(pool_strides) + [1],\n",
    "        padding = 'SAME'\n",
    "    )"
   ]
  },
  {
   "cell_type": "code",
   "execution_count": 37,
   "id": "172f80fc",
   "metadata": {},
   "outputs": [],
   "source": [
    "def flatten(x_tensor):\n",
    "    \"\"\"\n",
    "    Flatten x_tensor to (Batch Size, Flattened Image Size)\n",
    "    : x_tensor: A tensor of size (Batch Size, ...), where ... are the image dimensions.\n",
    "    : return: A tensor of size (Batch Size, Flattened Image Size).\n",
    "    \"\"\"\n",
    "    return tf.reshape(x_tensor, [-1, np.prod(x_tensor.shape.as_list()[1:])])"
   ]
  },
  {
   "cell_type": "code",
   "execution_count": 38,
   "id": "8813581f",
   "metadata": {},
   "outputs": [],
   "source": [
    "def fully_conn(x_tensor, num_outputs):\n",
    "    \"\"\"\n",
    "    Apply a fully connected layer to x_tensor using weight and bias\n",
    "    : x_tensor: A 2-D tensor where the first dimension is batch size.\n",
    "    : num_outputs: The number of output that the new tensor should be.\n",
    "    : return: A 2-D tensor where the second dimension is num_outputs.\n",
    "    \"\"\"\n",
    "    # Weights and bias\n",
    "    W = tf.Variable(tf.truncated_normal([int(x_tensor.shape[1]), num_outputs], stddev=.05))\n",
    "    b = tf.Variable(tf.zeros([num_outputs]))\n",
    "    \n",
    "    # The fully connected layer\n",
    "    x = tf.add(tf.matmul(x_tensor, W), b)\n",
    "    \n",
    "    # ReLU activation function\n",
    "    return tf.nn.relu(x)"
   ]
  },
  {
   "cell_type": "code",
   "execution_count": 39,
   "id": "97f847e1",
   "metadata": {},
   "outputs": [],
   "source": [
    "def output(x_tensor, num_outputs):\n",
    "    \"\"\"\n",
    "    Apply a output layer to x_tensor using weight and bias\n",
    "    : x_tensor: A 2-D tensor where the first dimension is batch size.\n",
    "    : num_outputs: The number of output that the new tensor should be.\n",
    "    : return: A 2-D tensor where the second dimension is num_outputs.\n",
    "    \"\"\"\n",
    "    # Weights and bias\n",
    "    W = tf.Variable(tf.truncated_normal([int(x_tensor.shape[1]), num_outputs], stddev=.05))\n",
    "    b = tf.Variable(tf.zeros([num_outputs]))\n",
    "    \n",
    "    # The output layer\n",
    "    return tf.add(tf.matmul(x_tensor, W), b)"
   ]
  },
  {
   "cell_type": "code",
   "execution_count": 40,
   "id": "31e265a2",
   "metadata": {},
   "outputs": [],
   "source": [
    "def conv_net(x, keep_prob):\n",
    "    \"\"\"\n",
    "    Create a convolutional neural network model\n",
    "    : x: Placeholder tensor that holds image data.\n",
    "    : keep_prob: Placeholder tensor that hold dropout keep probability.\n",
    "    : return: Tensor that represents logits\n",
    "    \"\"\"\n",
    "    # 3 convolution layers with max pooling\n",
    "    # All layers with same kernel, stride and maxpooling params\n",
    "    x = conv2d_maxpool(x, 64, (3,3), (1,1), (2,2), (2,2))\n",
    "    x = conv2d_maxpool(x, 128, (3,3), (1,1), (2,2), (2,2))\n",
    "    x = conv2d_maxpool(x, 256, (3,3), (1,1), (2,2), (2,2))\n",
    "    \n",
    "    # dropout after convolutions\n",
    "    x = tf.nn.dropout(x, keep_prob)\n",
    "    \n",
    "    # flatten layer\n",
    "    x = flatten(x)\n",
    "\n",
    "    # 1 fully connected layer followed by dropout\n",
    "    x = fully_conn(x, 1024)\n",
    "    x = tf.nn.dropout(x, keep_prob)\n",
    "    \n",
    "    # output layer\n",
    "    return output(x, 10)\n"
   ]
  },
  {
   "cell_type": "code",
   "execution_count": 41,
   "id": "104c2462",
   "metadata": {},
   "outputs": [],
   "source": [
    "# Remove previous weights, bias, inputs, etc..\n",
    "tf.reset_default_graph()\n",
    "\n",
    "# Inputs\n",
    "x = tf.placeholder(tf.float32, [None, 32, 32, 3], name=\"x\")\n",
    "y = tf.placeholder(tf.float32, [None, 10], name=\"y\")\n",
    "keep_prob = tf.placeholder(tf.float32, name=\"keep_prob\")\n",
    "\n",
    "# Model\n",
    "logits = conv_net(x, keep_prob)\n",
    "\n",
    "# Name logits Tensor, so that is can be loaded from disk after training\n",
    "logits = tf.identity(logits, name='logits')\n",
    "\n",
    "# Loss and Optimizer\n",
    "cost = tf.reduce_mean(tf.nn.softmax_cross_entropy_with_logits(logits=logits, labels=y))\n",
    "optimizer = tf.train.AdamOptimizer().minimize(cost)\n",
    "\n",
    "# Accuracy\n",
    "correct_pred = tf.equal(tf.argmax(logits, 1), tf.argmax(y, 1))\n",
    "accuracy = tf.reduce_mean(tf.cast(correct_pred, tf.float32), name='accuracy')\n"
   ]
  },
  {
   "cell_type": "code",
   "execution_count": 42,
   "id": "f0cf45c3",
   "metadata": {},
   "outputs": [],
   "source": [
    "def print_stats(session, feature_batch, label_batch, cost, accuracy):\n",
    "    \"\"\"\n",
    "    Print information about loss and validation accuracy\n",
    "    : session: Current TensorFlow session\n",
    "    : feature_batch: Batch of Numpy image data\n",
    "    : label_batch: Batch of Numpy label data\n",
    "    : cost: TensorFlow cost function\n",
    "    : accuracy: TensorFlow accuracy function\n",
    "    \"\"\"\n",
    "    global valid_features, valid_labels\n",
    "    loss = sess.run(cost, feed_dict={x: feature_batch, y: label_batch, keep_prob: 1.})\n",
    "    valid_acc = sess.run(\n",
    "        accuracy, \n",
    "        feed_dict={\n",
    "            x: norm_test_feats,\n",
    "            y: one_hot_test_lbls,\n",
    "            keep_prob: 1.\n",
    "        }\n",
    "    )\n",
    "    print('Loss: {:>8.4f}, Validation Accuracy: {:>8.6f}'.format(loss, valid_acc))"
   ]
  },
  {
   "cell_type": "code",
   "execution_count": 43,
   "id": "7c9e3d00",
   "metadata": {},
   "outputs": [],
   "source": [
    "epochs = 80\n",
    "batch_size = 1024\n",
    "keep_probability = 0.5\n"
   ]
  },
  {
   "cell_type": "code",
   "execution_count": 44,
   "id": "b853adb7",
   "metadata": {},
   "outputs": [],
   "source": [
    "def batch_features_labels(features, labels, batch_size):\n",
    "    \"\"\"\n",
    "    Split features and labels into batches\n",
    "    \"\"\"\n",
    "    for start in range(0, len(features), batch_size):\n",
    "        end = min(start + batch_size, len(features))\n",
    "        yield features[start:end], labels[start:end]\n",
    "\n",
    "\n",
    "def load_preprocess_training_batch(batch_id, batch_size):\n",
    "    \"\"\"\n",
    "    Load the Preprocessed Training data and return them in batches of <batch_size> or less\n",
    "    \"\"\"\n",
    "    filename = 'preprocess_batch_' + str(batch_id) + '.p'\n",
    "    features, labels = pickle.load(open(filename, mode='rb'))\n",
    "\n",
    "    # Return the training data in batches of size <batch_size> or less\n",
    "    return batch_features_labels(features, labels, batch_size)"
   ]
  },
  {
   "cell_type": "code",
   "execution_count": null,
   "id": "1f010b78",
   "metadata": {
    "scrolled": true
   },
   "outputs": [
    {
     "name": "stdout",
     "output_type": "stream",
     "text": [
      "Training...\n",
      "Epoch  1, CIFAR-10 Batch 1:  Loss:   2.1813, Validation Accuracy: 0.270000\n",
      "Epoch  1, CIFAR-10 Batch 2:  Loss:   1.9550, Validation Accuracy: 0.330200\n",
      "Epoch  1, CIFAR-10 Batch 3:  "
     ]
    },
    {
     "name": "stderr",
     "output_type": "stream",
     "text": [
      "ERROR:root:Internal Python error in the inspect module.\n",
      "Below is the traceback from this internal error.\n",
      "\n",
      "ERROR:root:Internal Python error in the inspect module.\n",
      "Below is the traceback from this internal error.\n",
      "\n"
     ]
    },
    {
     "name": "stdout",
     "output_type": "stream",
     "text": [
      "Traceback (most recent call last):\n",
      "  File \"C:\\Users\\29459\\anaconda3\\envs\\python37\\lib\\site-packages\\IPython\\core\\interactiveshell.py\", line 3437, in run_code\n",
      "    exec(code_obj, self.user_global_ns, self.user_ns)\n",
      "  File \"<ipython-input-45-c2820def8aa2>\", line 20, in <module>\n",
      "    print_stats(sess, batch_features, batch_labels, cost, accuracy)\n",
      "  File \"<ipython-input-42-009eadadfde8>\", line 17, in print_stats\n",
      "    keep_prob: 1.\n",
      "  File \"C:\\Users\\29459\\anaconda3\\envs\\python37\\lib\\site-packages\\tensorflow_core\\python\\client\\session.py\", line 956, in run\n",
      "    run_metadata_ptr)\n",
      "  File \"C:\\Users\\29459\\anaconda3\\envs\\python37\\lib\\site-packages\\tensorflow_core\\python\\client\\session.py\", line 1180, in _run\n",
      "    feed_dict_tensor, options, run_metadata)\n",
      "  File \"C:\\Users\\29459\\anaconda3\\envs\\python37\\lib\\site-packages\\tensorflow_core\\python\\client\\session.py\", line 1359, in _do_run\n",
      "    run_metadata)\n",
      "  File \"C:\\Users\\29459\\anaconda3\\envs\\python37\\lib\\site-packages\\tensorflow_core\\python\\client\\session.py\", line 1365, in _do_call\n",
      "    return fn(*args)\n",
      "  File \"C:\\Users\\29459\\anaconda3\\envs\\python37\\lib\\site-packages\\tensorflow_core\\python\\client\\session.py\", line 1350, in _run_fn\n",
      "    target_list, run_metadata)\n",
      "  File \"C:\\Users\\29459\\anaconda3\\envs\\python37\\lib\\site-packages\\tensorflow_core\\python\\client\\session.py\", line 1443, in _call_tf_sessionrun\n",
      "    run_metadata)\n",
      "KeyboardInterrupt\n",
      "\n",
      "During handling of the above exception, another exception occurred:\n",
      "\n",
      "Traceback (most recent call last):\n",
      "  File \"C:\\Users\\29459\\anaconda3\\envs\\python37\\lib\\site-packages\\IPython\\core\\interactiveshell.py\", line 2061, in showtraceback\n",
      "    stb = value._render_traceback_()\n",
      "AttributeError: 'KeyboardInterrupt' object has no attribute '_render_traceback_'\n",
      "\n",
      "During handling of the above exception, another exception occurred:\n",
      "\n",
      "Traceback (most recent call last):\n",
      "  File \"C:\\Users\\29459\\anaconda3\\envs\\python37\\lib\\site-packages\\IPython\\core\\ultratb.py\", line 1101, in get_records\n",
      "    return _fixed_getinnerframes(etb, number_of_lines_of_context, tb_offset)\n",
      "  File \"C:\\Users\\29459\\anaconda3\\envs\\python37\\lib\\site-packages\\IPython\\core\\ultratb.py\", line 248, in wrapped\n",
      "    return f(*args, **kwargs)\n",
      "  File \"C:\\Users\\29459\\anaconda3\\envs\\python37\\lib\\site-packages\\IPython\\core\\ultratb.py\", line 281, in _fixed_getinnerframes\n",
      "    records = fix_frame_records_filenames(inspect.getinnerframes(etb, context))\n",
      "  File \"C:\\Users\\29459\\anaconda3\\envs\\python37\\lib\\inspect.py\", line 1502, in getinnerframes\n",
      "    frameinfo = (tb.tb_frame,) + getframeinfo(tb, context)\n",
      "  File \"C:\\Users\\29459\\anaconda3\\envs\\python37\\lib\\inspect.py\", line 1460, in getframeinfo\n",
      "    filename = getsourcefile(frame) or getfile(frame)\n",
      "  File \"C:\\Users\\29459\\anaconda3\\envs\\python37\\lib\\inspect.py\", line 696, in getsourcefile\n",
      "    if getattr(getmodule(object, filename), '__loader__', None) is not None:\n",
      "  File \"C:\\Users\\29459\\anaconda3\\envs\\python37\\lib\\inspect.py\", line 733, in getmodule\n",
      "    if ismodule(module) and hasattr(module, '__file__'):\n",
      "  File \"C:\\Users\\29459\\anaconda3\\envs\\python37\\lib\\site-packages\\tensorflow\\__init__.py\", line 50, in __getattr__\n",
      "    module = self._load()\n",
      "  File \"C:\\Users\\29459\\anaconda3\\envs\\python37\\lib\\site-packages\\tensorflow\\__init__.py\", line 44, in _load\n",
      "    module = _importlib.import_module(self.__name__)\n",
      "  File \"C:\\Users\\29459\\anaconda3\\envs\\python37\\lib\\importlib\\__init__.py\", line 127, in import_module\n",
      "    return _bootstrap._gcd_import(name[level:], package, level)\n",
      "  File \"<frozen importlib._bootstrap>\", line 1006, in _gcd_import\n",
      "  File \"<frozen importlib._bootstrap>\", line 983, in _find_and_load\n",
      "  File \"<frozen importlib._bootstrap>\", line 965, in _find_and_load_unlocked\n",
      "ModuleNotFoundError: No module named 'tensorflow_core.estimator'\n",
      "Traceback (most recent call last):\n",
      "  File \"C:\\Users\\29459\\anaconda3\\envs\\python37\\lib\\site-packages\\IPython\\core\\interactiveshell.py\", line 3437, in run_code\n",
      "    exec(code_obj, self.user_global_ns, self.user_ns)\n",
      "  File \"<ipython-input-45-c2820def8aa2>\", line 20, in <module>\n",
      "    print_stats(sess, batch_features, batch_labels, cost, accuracy)\n",
      "  File \"<ipython-input-42-009eadadfde8>\", line 17, in print_stats\n",
      "    keep_prob: 1.\n",
      "  File \"C:\\Users\\29459\\anaconda3\\envs\\python37\\lib\\site-packages\\tensorflow_core\\python\\client\\session.py\", line 956, in run\n",
      "    run_metadata_ptr)\n",
      "  File \"C:\\Users\\29459\\anaconda3\\envs\\python37\\lib\\site-packages\\tensorflow_core\\python\\client\\session.py\", line 1180, in _run\n",
      "    feed_dict_tensor, options, run_metadata)\n",
      "  File \"C:\\Users\\29459\\anaconda3\\envs\\python37\\lib\\site-packages\\tensorflow_core\\python\\client\\session.py\", line 1359, in _do_run\n",
      "    run_metadata)\n",
      "  File \"C:\\Users\\29459\\anaconda3\\envs\\python37\\lib\\site-packages\\tensorflow_core\\python\\client\\session.py\", line 1365, in _do_call\n",
      "    return fn(*args)\n",
      "  File \"C:\\Users\\29459\\anaconda3\\envs\\python37\\lib\\site-packages\\tensorflow_core\\python\\client\\session.py\", line 1350, in _run_fn\n",
      "    target_list, run_metadata)\n",
      "  File \"C:\\Users\\29459\\anaconda3\\envs\\python37\\lib\\site-packages\\tensorflow_core\\python\\client\\session.py\", line 1443, in _call_tf_sessionrun\n",
      "    run_metadata)\n",
      "KeyboardInterrupt\n",
      "\n",
      "During handling of the above exception, another exception occurred:\n",
      "\n",
      "Traceback (most recent call last):\n",
      "  File \"C:\\Users\\29459\\anaconda3\\envs\\python37\\lib\\site-packages\\IPython\\core\\interactiveshell.py\", line 2061, in showtraceback\n",
      "    stb = value._render_traceback_()\n",
      "AttributeError: 'KeyboardInterrupt' object has no attribute '_render_traceback_'\n",
      "\n",
      "During handling of the above exception, another exception occurred:\n",
      "\n",
      "Traceback (most recent call last):\n",
      "  File \"C:\\Users\\29459\\anaconda3\\envs\\python37\\lib\\site-packages\\IPython\\core\\interactiveshell.py\", line 3357, in run_ast_nodes\n",
      "    if (await self.run_code(code, result,  async_=asy)):\n",
      "  File \"C:\\Users\\29459\\anaconda3\\envs\\python37\\lib\\site-packages\\IPython\\core\\interactiveshell.py\", line 3454, in run_code\n",
      "    self.showtraceback(running_compiled_code=True)\n",
      "  File \"C:\\Users\\29459\\anaconda3\\envs\\python37\\lib\\site-packages\\IPython\\core\\interactiveshell.py\", line 2064, in showtraceback\n",
      "    value, tb, tb_offset=tb_offset)\n",
      "  File \"C:\\Users\\29459\\anaconda3\\envs\\python37\\lib\\site-packages\\IPython\\core\\ultratb.py\", line 1368, in structured_traceback\n",
      "    self, etype, value, tb, tb_offset, number_of_lines_of_context)\n",
      "  File \"C:\\Users\\29459\\anaconda3\\envs\\python37\\lib\\site-packages\\IPython\\core\\ultratb.py\", line 1268, in structured_traceback\n",
      "    self, etype, value, tb, tb_offset, number_of_lines_of_context\n",
      "  File \"C:\\Users\\29459\\anaconda3\\envs\\python37\\lib\\site-packages\\IPython\\core\\ultratb.py\", line 1125, in structured_traceback\n",
      "    tb_offset)\n",
      "  File \"C:\\Users\\29459\\anaconda3\\envs\\python37\\lib\\site-packages\\IPython\\core\\ultratb.py\", line 1082, in format_exception_as_a_whole\n",
      "    last_unique, recursion_repeat = find_recursion(orig_etype, evalue, records)\n",
      "  File \"C:\\Users\\29459\\anaconda3\\envs\\python37\\lib\\site-packages\\IPython\\core\\ultratb.py\", line 382, in find_recursion\n",
      "    return len(records), 0\n",
      "TypeError: object of type 'NoneType' has no len()\n",
      "\n",
      "During handling of the above exception, another exception occurred:\n",
      "\n",
      "Traceback (most recent call last):\n",
      "  File \"C:\\Users\\29459\\anaconda3\\envs\\python37\\lib\\site-packages\\IPython\\core\\interactiveshell.py\", line 2061, in showtraceback\n",
      "    stb = value._render_traceback_()\n",
      "AttributeError: 'TypeError' object has no attribute '_render_traceback_'\n",
      "\n",
      "During handling of the above exception, another exception occurred:\n",
      "\n",
      "Traceback (most recent call last):\n",
      "  File \"C:\\Users\\29459\\anaconda3\\envs\\python37\\lib\\site-packages\\IPython\\core\\ultratb.py\", line 1101, in get_records\n",
      "    return _fixed_getinnerframes(etb, number_of_lines_of_context, tb_offset)\n",
      "  File \"C:\\Users\\29459\\anaconda3\\envs\\python37\\lib\\site-packages\\IPython\\core\\ultratb.py\", line 248, in wrapped\n",
      "    return f(*args, **kwargs)\n",
      "  File \"C:\\Users\\29459\\anaconda3\\envs\\python37\\lib\\site-packages\\IPython\\core\\ultratb.py\", line 281, in _fixed_getinnerframes\n",
      "    records = fix_frame_records_filenames(inspect.getinnerframes(etb, context))\n",
      "  File \"C:\\Users\\29459\\anaconda3\\envs\\python37\\lib\\inspect.py\", line 1502, in getinnerframes\n",
      "    frameinfo = (tb.tb_frame,) + getframeinfo(tb, context)\n",
      "  File \"C:\\Users\\29459\\anaconda3\\envs\\python37\\lib\\inspect.py\", line 1460, in getframeinfo\n",
      "    filename = getsourcefile(frame) or getfile(frame)\n",
      "  File \"C:\\Users\\29459\\anaconda3\\envs\\python37\\lib\\inspect.py\", line 696, in getsourcefile\n",
      "    if getattr(getmodule(object, filename), '__loader__', None) is not None:\n",
      "  File \"C:\\Users\\29459\\anaconda3\\envs\\python37\\lib\\inspect.py\", line 733, in getmodule\n",
      "    if ismodule(module) and hasattr(module, '__file__'):\n",
      "  File \"C:\\Users\\29459\\anaconda3\\envs\\python37\\lib\\site-packages\\tensorflow\\__init__.py\", line 50, in __getattr__\n",
      "    module = self._load()\n",
      "  File \"C:\\Users\\29459\\anaconda3\\envs\\python37\\lib\\site-packages\\tensorflow\\__init__.py\", line 44, in _load\n",
      "    module = _importlib.import_module(self.__name__)\n",
      "  File \"C:\\Users\\29459\\anaconda3\\envs\\python37\\lib\\importlib\\__init__.py\", line 127, in import_module\n",
      "    return _bootstrap._gcd_import(name[level:], package, level)\n",
      "  File \"<frozen importlib._bootstrap>\", line 1006, in _gcd_import\n",
      "  File \"<frozen importlib._bootstrap>\", line 983, in _find_and_load\n",
      "  File \"<frozen importlib._bootstrap>\", line 965, in _find_and_load_unlocked\n",
      "ModuleNotFoundError: No module named 'tensorflow_core.estimator'\n"
     ]
    },
    {
     "name": "stderr",
     "output_type": "stream",
     "text": [
      "ERROR:root:Internal Python error in the inspect module.\n",
      "Below is the traceback from this internal error.\n",
      "\n"
     ]
    },
    {
     "name": "stdout",
     "output_type": "stream",
     "text": [
      "Traceback (most recent call last):\n",
      "  File \"C:\\Users\\29459\\anaconda3\\envs\\python37\\lib\\site-packages\\IPython\\core\\interactiveshell.py\", line 3437, in run_code\n",
      "    exec(code_obj, self.user_global_ns, self.user_ns)\n",
      "  File \"<ipython-input-45-c2820def8aa2>\", line 20, in <module>\n",
      "    print_stats(sess, batch_features, batch_labels, cost, accuracy)\n",
      "  File \"<ipython-input-42-009eadadfde8>\", line 17, in print_stats\n",
      "    keep_prob: 1.\n",
      "  File \"C:\\Users\\29459\\anaconda3\\envs\\python37\\lib\\site-packages\\tensorflow_core\\python\\client\\session.py\", line 956, in run\n",
      "    run_metadata_ptr)\n",
      "  File \"C:\\Users\\29459\\anaconda3\\envs\\python37\\lib\\site-packages\\tensorflow_core\\python\\client\\session.py\", line 1180, in _run\n",
      "    feed_dict_tensor, options, run_metadata)\n",
      "  File \"C:\\Users\\29459\\anaconda3\\envs\\python37\\lib\\site-packages\\tensorflow_core\\python\\client\\session.py\", line 1359, in _do_run\n",
      "    run_metadata)\n",
      "  File \"C:\\Users\\29459\\anaconda3\\envs\\python37\\lib\\site-packages\\tensorflow_core\\python\\client\\session.py\", line 1365, in _do_call\n",
      "    return fn(*args)\n",
      "  File \"C:\\Users\\29459\\anaconda3\\envs\\python37\\lib\\site-packages\\tensorflow_core\\python\\client\\session.py\", line 1350, in _run_fn\n",
      "    target_list, run_metadata)\n",
      "  File \"C:\\Users\\29459\\anaconda3\\envs\\python37\\lib\\site-packages\\tensorflow_core\\python\\client\\session.py\", line 1443, in _call_tf_sessionrun\n",
      "    run_metadata)\n",
      "KeyboardInterrupt\n",
      "\n",
      "During handling of the above exception, another exception occurred:\n",
      "\n",
      "Traceback (most recent call last):\n",
      "  File \"C:\\Users\\29459\\anaconda3\\envs\\python37\\lib\\site-packages\\IPython\\core\\interactiveshell.py\", line 2061, in showtraceback\n",
      "    stb = value._render_traceback_()\n",
      "AttributeError: 'KeyboardInterrupt' object has no attribute '_render_traceback_'\n",
      "\n",
      "During handling of the above exception, another exception occurred:\n",
      "\n",
      "Traceback (most recent call last):\n",
      "  File \"C:\\Users\\29459\\anaconda3\\envs\\python37\\lib\\site-packages\\IPython\\core\\interactiveshell.py\", line 3357, in run_ast_nodes\n",
      "    if (await self.run_code(code, result,  async_=asy)):\n",
      "  File \"C:\\Users\\29459\\anaconda3\\envs\\python37\\lib\\site-packages\\IPython\\core\\interactiveshell.py\", line 3454, in run_code\n",
      "    self.showtraceback(running_compiled_code=True)\n",
      "  File \"C:\\Users\\29459\\anaconda3\\envs\\python37\\lib\\site-packages\\IPython\\core\\interactiveshell.py\", line 2064, in showtraceback\n",
      "    value, tb, tb_offset=tb_offset)\n",
      "  File \"C:\\Users\\29459\\anaconda3\\envs\\python37\\lib\\site-packages\\IPython\\core\\ultratb.py\", line 1368, in structured_traceback\n",
      "    self, etype, value, tb, tb_offset, number_of_lines_of_context)\n",
      "  File \"C:\\Users\\29459\\anaconda3\\envs\\python37\\lib\\site-packages\\IPython\\core\\ultratb.py\", line 1268, in structured_traceback\n",
      "    self, etype, value, tb, tb_offset, number_of_lines_of_context\n",
      "  File \"C:\\Users\\29459\\anaconda3\\envs\\python37\\lib\\site-packages\\IPython\\core\\ultratb.py\", line 1125, in structured_traceback\n",
      "    tb_offset)\n",
      "  File \"C:\\Users\\29459\\anaconda3\\envs\\python37\\lib\\site-packages\\IPython\\core\\ultratb.py\", line 1082, in format_exception_as_a_whole\n",
      "    last_unique, recursion_repeat = find_recursion(orig_etype, evalue, records)\n",
      "  File \"C:\\Users\\29459\\anaconda3\\envs\\python37\\lib\\site-packages\\IPython\\core\\ultratb.py\", line 382, in find_recursion\n",
      "    return len(records), 0\n",
      "TypeError: object of type 'NoneType' has no len()\n",
      "\n",
      "During handling of the above exception, another exception occurred:\n",
      "\n",
      "Traceback (most recent call last):\n",
      "  File \"C:\\Users\\29459\\anaconda3\\envs\\python37\\lib\\site-packages\\IPython\\core\\interactiveshell.py\", line 2061, in showtraceback\n",
      "    stb = value._render_traceback_()\n",
      "AttributeError: 'TypeError' object has no attribute '_render_traceback_'\n",
      "\n",
      "During handling of the above exception, another exception occurred:\n",
      "\n",
      "Traceback (most recent call last):\n",
      "  File \"C:\\Users\\29459\\anaconda3\\envs\\python37\\lib\\site-packages\\IPython\\core\\interactiveshell.py\", line 2940, in _run_cell\n",
      "    return runner(coro)\n",
      "  File \"C:\\Users\\29459\\anaconda3\\envs\\python37\\lib\\site-packages\\IPython\\core\\async_helpers.py\", line 68, in _pseudo_sync_runner\n",
      "    coro.send(None)\n",
      "  File \"C:\\Users\\29459\\anaconda3\\envs\\python37\\lib\\site-packages\\IPython\\core\\interactiveshell.py\", line 3166, in run_cell_async\n",
      "    interactivity=interactivity, compiler=compiler, result=result)\n",
      "  File \"C:\\Users\\29459\\anaconda3\\envs\\python37\\lib\\site-packages\\IPython\\core\\interactiveshell.py\", line 3376, in run_ast_nodes\n",
      "    self.showtraceback()\n",
      "  File \"C:\\Users\\29459\\anaconda3\\envs\\python37\\lib\\site-packages\\IPython\\core\\interactiveshell.py\", line 2064, in showtraceback\n",
      "    value, tb, tb_offset=tb_offset)\n",
      "  File \"C:\\Users\\29459\\anaconda3\\envs\\python37\\lib\\site-packages\\IPython\\core\\ultratb.py\", line 1368, in structured_traceback\n",
      "    self, etype, value, tb, tb_offset, number_of_lines_of_context)\n",
      "  File \"C:\\Users\\29459\\anaconda3\\envs\\python37\\lib\\site-packages\\IPython\\core\\ultratb.py\", line 1268, in structured_traceback\n",
      "    self, etype, value, tb, tb_offset, number_of_lines_of_context\n",
      "  File \"C:\\Users\\29459\\anaconda3\\envs\\python37\\lib\\site-packages\\IPython\\core\\ultratb.py\", line 1143, in structured_traceback\n",
      "    chained_exceptions_tb_offset)\n",
      "  File \"C:\\Users\\29459\\anaconda3\\envs\\python37\\lib\\site-packages\\IPython\\core\\ultratb.py\", line 1082, in format_exception_as_a_whole\n",
      "    last_unique, recursion_repeat = find_recursion(orig_etype, evalue, records)\n",
      "  File \"C:\\Users\\29459\\anaconda3\\envs\\python37\\lib\\site-packages\\IPython\\core\\ultratb.py\", line 382, in find_recursion\n",
      "    return len(records), 0\n",
      "TypeError: object of type 'NoneType' has no len()\n",
      "\n",
      "During handling of the above exception, another exception occurred:\n",
      "\n",
      "Traceback (most recent call last):\n",
      "  File \"C:\\Users\\29459\\anaconda3\\envs\\python37\\lib\\site-packages\\IPython\\core\\interactiveshell.py\", line 2061, in showtraceback\n",
      "    stb = value._render_traceback_()\n",
      "AttributeError: 'TypeError' object has no attribute '_render_traceback_'\n",
      "\n",
      "During handling of the above exception, another exception occurred:\n",
      "\n",
      "Traceback (most recent call last):\n",
      "  File \"C:\\Users\\29459\\anaconda3\\envs\\python37\\lib\\site-packages\\IPython\\core\\ultratb.py\", line 1101, in get_records\n",
      "    return _fixed_getinnerframes(etb, number_of_lines_of_context, tb_offset)\n",
      "  File \"C:\\Users\\29459\\anaconda3\\envs\\python37\\lib\\site-packages\\IPython\\core\\ultratb.py\", line 248, in wrapped\n",
      "    return f(*args, **kwargs)\n",
      "  File \"C:\\Users\\29459\\anaconda3\\envs\\python37\\lib\\site-packages\\IPython\\core\\ultratb.py\", line 281, in _fixed_getinnerframes\n",
      "    records = fix_frame_records_filenames(inspect.getinnerframes(etb, context))\n",
      "  File \"C:\\Users\\29459\\anaconda3\\envs\\python37\\lib\\inspect.py\", line 1502, in getinnerframes\n",
      "    frameinfo = (tb.tb_frame,) + getframeinfo(tb, context)\n",
      "  File \"C:\\Users\\29459\\anaconda3\\envs\\python37\\lib\\inspect.py\", line 1460, in getframeinfo\n",
      "    filename = getsourcefile(frame) or getfile(frame)\n",
      "  File \"C:\\Users\\29459\\anaconda3\\envs\\python37\\lib\\inspect.py\", line 696, in getsourcefile\n",
      "    if getattr(getmodule(object, filename), '__loader__', None) is not None:\n",
      "  File \"C:\\Users\\29459\\anaconda3\\envs\\python37\\lib\\inspect.py\", line 733, in getmodule\n",
      "    if ismodule(module) and hasattr(module, '__file__'):\n",
      "  File \"C:\\Users\\29459\\anaconda3\\envs\\python37\\lib\\site-packages\\tensorflow\\__init__.py\", line 50, in __getattr__\n",
      "    module = self._load()\n",
      "  File \"C:\\Users\\29459\\anaconda3\\envs\\python37\\lib\\site-packages\\tensorflow\\__init__.py\", line 44, in _load\n",
      "    module = _importlib.import_module(self.__name__)\n",
      "  File \"C:\\Users\\29459\\anaconda3\\envs\\python37\\lib\\importlib\\__init__.py\", line 127, in import_module\n",
      "    return _bootstrap._gcd_import(name[level:], package, level)\n",
      "  File \"<frozen importlib._bootstrap>\", line 1006, in _gcd_import\n",
      "  File \"<frozen importlib._bootstrap>\", line 983, in _find_and_load\n",
      "  File \"<frozen importlib._bootstrap>\", line 965, in _find_and_load_unlocked\n",
      "ModuleNotFoundError: No module named 'tensorflow_core.estimator'\n"
     ]
    }
   ],
   "source": [
    "print(\"Training...\")\n",
    "with tf.Session() as sess:\n",
    "    # Initializing the variables\n",
    "    sess.run(tf.global_variables_initializer())\n",
    "    \n",
    "    # Training cycle\n",
    "    for epoch in range(epochs):\n",
    "        n_batches = 5\n",
    "        for batch_i in range(1, n_batches+1):\n",
    "            for batch_features, batch_labels in load_preprocess_training_batch(batch_i, batch_size):\n",
    "                sess.run(\n",
    "                    optimizer, \n",
    "                    feed_dict={\n",
    "                        x: batch_features, \n",
    "                        y: batch_labels, \n",
    "                        keep_prob: keep_probability\n",
    "                    }\n",
    "                )\n",
    "            print('Epoch {:>2}, CIFAR-10 Batch {}:  '.format(epoch + 1, batch_i), end='')\n",
    "            print_stats(sess, batch_features, batch_labels, cost, accuracy)\n",
    "    \n",
    "    # Save Model\n",
    "    saver = tf.train.Saver()\n",
    "    save_path = saver.save(sess, './image_classification')"
   ]
  },
  {
   "cell_type": "code",
   "execution_count": null,
   "id": "7a8bb082",
   "metadata": {},
   "outputs": [],
   "source": []
  },
  {
   "cell_type": "code",
   "execution_count": null,
   "id": "696ee273",
   "metadata": {},
   "outputs": [],
   "source": []
  }
 ],
 "metadata": {
  "kernelspec": {
   "display_name": "Python 3",
   "language": "python",
   "name": "python3"
  },
  "language_info": {
   "codemirror_mode": {
    "name": "ipython",
    "version": 3
   },
   "file_extension": ".py",
   "mimetype": "text/x-python",
   "name": "python",
   "nbconvert_exporter": "python",
   "pygments_lexer": "ipython3",
   "version": "3.7.10"
  }
 },
 "nbformat": 4,
 "nbformat_minor": 5
}
